Workbook
Name DPS: #REF!
Name _AUG02: #REF!
Name perp_lev2: #REF!
Name kit: #REF!
Name TOOLBOX: #REF!
Name CF_begcash: #REF!
Name _8GG2_: #REF!
Name OPGRPRQ1: #REF!
Name IDP: #REF!
Name _4QTRFIN: #REF!
Name acq_cost_convert_low: #REF!
Name NewCo3ON: #REF!
Name SIDEntities: #REF!
Name LBOIPOExit1: #REF!
Name _Pg58: #REF!
Name Periods: #REF!
Name Procurementph: #REF!
Name fisher: #REF!
Name MENU: #REF!
Name Subrelated: #REF!
Name DownlodedOn: 'philips deals'!$F$4
Name codes: #REF!
Name CustRev: #REF!
Name WACC_sen: #REF!
Name Buys: #REF!
Name _GPQ3: #REF!
Name ManagementEBIT: #REF!
Name ccy: #REF!
Name IS_inctaxes: #REF!
Name CF_Other_CA: #REF!
Name _inv2: #REF!
Name PPDIAG2003: #REF!
Name FIGEADQ1: #REF!
Name page5: #REF!
Name LoanPmt: #REF!
Name actsummy: #REF!
Name FIGM95: #REF!
Name GPPFINQ3: #REF!
Name AsiaPL: #REF!
Name FINQ1: #REF!
Name CF_straightdebt: #REF!
Name MonthTable: #REF!
Name SmaxFOA: #REF!
Name terminal_year: #REF!
Name QAph: #REF!
Name FINOIQ4: #REF!
Name c_pageswitch: #REF!
Name CF_Inventory: #REF!
Name Graphs_2: #REF!
Name EuropePL: #REF!
Name BurnhamProdConph: #REF!
Name BkgsByProdline: #REF!
Name BS_AP: #REF!
Name _Pg32: #REF!
Name WDGRPRQ4: #REF!
Name BEGRSLQ1: #REF!
Name CF_deferredtaxes: #REF!
Name RF_International: #REF!
Name BkgsByProdline: #REF!
Name TOOL91: #REF!

Sheet JILL
G1: FITBIT BASE | H1: FIT STANDALONE CASE | L1: FIT STANDALONE + SYNERGY CASE
F2: 2017A | G2: 2018A | H2: 2019 1 | I2: 2020 | J2: 2021 | L2: 2019 | M2: 2020 | N2: 2021
B4: Net Revenue | F4: 24.9 | G4: 27.1 | H4: =14.5+17.3 -> 31.8 | I4: =45.2 -> 45.2 | J4: =60.1 -> 60.1 | L4: =14.5+19.3 -> 33.8 | M4: 59.73 | N4: 80.5
B5: Growth % | C5: 0.32 | D5: 0.4 | F5: 0.18757834 | G5: 0.088353414 | H5: =H4/G4-1 -> 0.17343173 | I5: =I4/H4-1 -> 0.42138365 | J5: =J4/I4-1 -> 0.32964602 | M5: =M4/L4-1 -> 0.76715976 | N5: =N4/M4-1 -> 0.34773146
B7: COGS | F7: 9.4435091 | G7: 10.942581 | H7: =5.41+7.41 -> 12.82 | I7: 16.43 | J7: 23.12 | L7: =5.4+8.2 -> 13.6 | M7: 22.06 | N7: 31.1
B8: % Revenue | C8: 0 | D8: 0 | F8: =F7/F4 -> 0.37925739 | G8: =G7/G4 -> 0.40378528 | H8: =H7/H4 -> 0.40314465 | I8: =I7/I4 -> 0.36349558 | J8: =J7/J4 -> 0.38469218 | L8: =L7/L4 -> 0.40236686 | M8: =M7/M4 -> 0.36932865 | N8: =N7/N4 -> 0.3863354
B10: GROSS PROFIT | F10: =F4-F7 -> 15.456491 | G10: =G4-G7 -> 16.157419 | H10: =H4-H7 -> 18.98 | I10: =I4-I7 -> 28.77 | J10: =J4-J7 -> 36.98 | L10: =L4-L7 -> 20.2 | M10: =M4-M7 -> 37.67 | N10: =N4-N7 -> 49.4
B11: % Margin | F11: =F10/F4 -> 0.62074261 | G11: =G10/G4 -> 0.59621472 | H11: =H10/H4 -> 0.59685535 | I11: =I10/I4 -> 0.63650442 | J11: =J10/J4 -> 0.61530782 | L11: =L10/L4 -> 0.59763314 | M11: =M10/M4 -> 0.63067135 | N11: =N10/N4 -> 0.6136646
B13: OPEX: | J13: ` | N13: `
B14: S&M | F14: 7.727007 | G14: 7.614628 | H14: =4+5.19 -> 9.19 | I14: =13 -> 13 | J14: =14.96 -> 14.96 | L14: =4+5.9 -> 9.9 | M14: 14.3 | N14: 16.4
A15: R&D | B15: G&A | F15: 7.308554 | G15: 6.992441 | H15: =0.12+0.12 -> 0.24 | I15: =0.24 -> 0.24 | J15: =0.24 -> 0.24 | L15: =0.1+1.6 -> 1.7 | M15: 3.4 | N15: 0.4
A16: G&A | B16: R&D | F16: 0.11225 | G16: 0.018178 | H16: =5.11+5.24 -> 10.35 | I16: =11.53 -> 11.53 | J16: =13.06 -> 13.06 | L16: =5.1+6.2 -> 11.3 | M16: 13.6 | N16: 15.1
B17: OPEX | F17: =SUM(F14:F16) -> 15.147811 | G17: =SUM(G14:G16) -> 14.625247 | H17: =SUM(H14:H16) -> 19.78 | I17: =SUM(I14:I16) -> 24.77 | J17: =SUM(J14:J16) -> 28.26 | L17: =SUM(L14:L16) -> 22.9 | M17: =SUM(M14:M16) -> 31.3 | N17: =SUM(N14:N16) -> 31.9
B18: % Revenue | F18: =F17/F4 -> 0.60834582 | G18: =G17/G4 -> 0.53967701 | H18: =H17/H4 -> 0.62201258 | I18: =I17/I4 -> 0.54800885 | J18: =J17/J4 -> 0.47021631 | L18: =L17/L4 -> 0.67751479 | M18: =M17/M4 -> 0.52402478 | N18: =N17/N4 -> 0.39627329
B20: OPEX % Revenue:
B21: S&M | C21: 0 | D21: 0 | F21: =F14/F$4 -> 0.31032157 | G21: =G14/G$4 -> 0.28098258 | H21: =H14/H$4 -> 0.28899371 | I21: =I14/I$4 -> 0.28761062 | J21: =I21+$C21 -> 0.28761062 | L21: =L14/L$4 -> 0.29289941 | M21: =M14/M$4 -> 0.23941068 | N21: =M21+$C21 -> 0.23941068
B22: G&A | C22: 0 | D22: 0 | F22: =F15/F$4 -> 0.29351622 | G22: =G15/G$4 -> 0.25802365 | H22: =H15/H$4 -> 0.0075471698 | I22: =I15/I$4 -> 0.0053097345 | J22: =I22+$C22 -> 0.0053097345 | L22: =L15/L$4 -> 0.050295858 | M22: =M15/M$4 -> 0.056922819 | N22: =M22+$C22 -> 0.056922819
B23: R&D | C23: 0 | D23: 0 | F23: =F16/F$4 -> 0.0045080321 | G23: =G16/G$4 -> 0.00067077491 | H23: =H16/H$4 -> 0.3254717 | I23: =I16/I$4 -> 0.2550885 | J23: =I23+$C23 -> 0.2550885 | L23: =L16/L$4 -> 0.33431953 | M23: =M16/M$4 -> 0.22769128 | N23: =M23+$C23 -> 0.22769128
B24: Total Opex % | F24: =SUM(F21:F23) -> 0.60834582 | G24: =SUM(G21:G23) -> 0.53967701 | H24: =SUM(H21:H23) -> 0.62201258 | I24: =SUM(I21:I23) -> 0.54800885 | J24: =SUM(J21:J23) -> 0.54800885 | L24: =SUM(L21:L23) -> 0.67751479 | M24: =SUM(M21:M23) -> 0.52402478 | N24: =SUM(N21:N23) -> 0.52402478
B26: EBIT | F26: =F10-F17 -> 0.30867991 | G26: =G10-G17 -> 1.532172 | H26: =H10-H17 -> -0.8 | I26: =I10-I17 -> 4 | J26: =J10-J17 -> 8.72 | L26: =L10-L17 -> -2.7 | M26: =M10-M17 -> 6.37 | N26: =N10-N17 -> 17.5
B27: % Margin | F27: =F26/F4 -> 0.012396784 | G27: =G26/G4 -> 0.056537712 | H27: =H26/H4 -> -0.025157233 | I27: =I26/I4 -> 0.088495575 | J27: =J26/J4 -> 0.14509151 | L27: =L26/L4 -> -0.079881657 | M27: =M26/M4 -> 0.10664658 | N27: =N26/N4 -> 0.2173913
B29: D&A | F29: 0.99483639 | G29: 2.2 | H29: =H35 -> 1.28 | I29: 1.3 | J29: 2.8 | L29: =0.3+0.4+0.32+0.32 -> 1.34 | M29: =2.1+0.32 -> 2.42 | N29: =3.9+0.32 -> 4.22
B30: % Revenue | C30: 0.05 | D30: =C30 -> 0.05 | F30: =F29/F4 -> 0.039953269 | G30: =G29/G4 -> 0.081180812 | H30: =H29/H4 -> 0.040251572 | I30: =I29/I4 -> 0.028761062 | J30: =J29/J4 -> 0.046589018 | L30: =L29/L4 -> 0.03964497 | M30: =M29/M4 -> 0.040515654 | N30: =N29/N4 -> 0.05242236
B32: EBITDA | F32: =F26+F29 -> 1.3035163 | G32: =G26+G29 -> 3.732172 | H32: =H26+H29 -> 0.48 | I32: =I26+I29 -> 5.3 | J32: =J26+J29 -> 11.52 | L32: =L26+L29 -> -1.36 | M32: =M26+M29 -> 8.79 | N32: =N26+N29 -> 21.72
B33: % Margin | F33: =F32/F4 -> 0.052350052 | G33: =G32/G4 -> 0.13771852 | H33: =H32/H4 -> 0.01509434 | I33: =I32/I4 -> 0.11725664 | J33: =J32/J4 -> 0.19168053 | L33: =L32/L4 -> -0.040236686 | M33: =M32/M4 -> 0.14716223 | N33: =N32/N4 -> 0.26981366
B35: Capex (HST) | F35: 0 | G35: 1 | H35: =(0.32*2)+(0.32*2) -> 1.28 | I35: =I29 -> 1.3 | J35: =J29 -> 2.8 | L35: =L29 -> 1.34 | M35: =M29 -> 2.42 | N35: =N29 -> 4.22
B36: % Revenue | C36: =C30 -> 0.05 | D36: =D30 -> 0.05 | F36: =F35/F4 -> 0 | G36: =G35/G4 -> 0.036900369 | H36: =H35/H4 -> 0.040251572 | I36: =I35/I4 -> 0.028761062 | J36: =J35/J4 -> 0.046589018 | L36: =L35/L4 -> 0.03964497 | M36: =M35/M4 -> 0.040515654 | N36: =N35/N4 -> 0.05242236
B38: NWC | C38: 0.15 | D38: 0.15 | G38: 1.452 | H38: 1.981 | I38: 2.156 | J38: 2.879 | L38: 2.359 | M38: 2.831 | N38: 3.927
B39: Change in NWC | H39: =H38-G38 -> 0.529 | I39: =I38-H38 -> 0.175 | J39: =J38-I38 -> 0.723 | M39: =M38-L38 -> 0.472 | N39: =N38-M38 -> 1.096
B40: % Sales | G40: =G38/G4 -> 0.053579336 | H40: =H38/H4 -> 0.062295597 | I40: =I38/I4 -> 0.047699115 | J40: =J38/J4 -> 0.047903494 | L40: =L38/L4 -> 0.069792899 | M40: =M38/M4 -> 0.047396618 | N40: =N38/N4 -> 0.048782609

Sheet Standalone Case
A1: STANDALONE CASE
F2: 2017A | G2: 2018A | H2: 2019 | I2: 2020 | J2: 2021 | K2: 2022 | L2: =K2+1 -> 2023 | M2: =L2+1 -> 2024 | N2: =M2+1 -> 2025 | O2: =N2+1 -> 2026 | P2: =O2+1 -> 2027 | Q2: =P2+1 -> 2028
B4: Net Revenue | F4: 23.20256 | G4: =JILL!G4 -> 27.1 | H4: =JILL!H4 -> 31.8 | I4: =JILL!I4 -> 45.2 | J4: =JILL!J4 -> 60.1 | K4: =J4*(1+K5) -> 73.6225 | L4: =K4*(1+L5) -> 86.506438 | M4: =L4*(1+M5) -> 99.482403 | N4: =M4*(1+N5) -> 111.9177 | O4: =N4*(1+O5) -> 123.10947 | P4: =O4*(1+P5) -> 132.34268 | Q4: =P4*(1+Q5) -> 138.95982
B5: Growth % | D5: 0.025 | F5: ='mgmt '!I25 -> 0.18757834 | G5: =G4/F4-1 -> 0.16797457 | H5: =H4/G4-1 -> 0.17343173 | I5: =I4/H4-1 -> 0.42138365 | J5: =J4/I4-1 -> 0.32964602 | K5: 0.225 | L5: 0.175 | M5: 0.15 | N5: =M5-$D$5 -> 0.125 | O5: =N5-$D$5 -> 0.1 | P5: =O5-$D$5 -> 0.075 | Q5: =P5-$D$5 -> 0.05
B7: COGS | F7: ='mgmt '!I48 -> 9.4435091 | G7: =JILL!G7 -> 10.942581 | H7: =JILL!H7 -> 12.82 | I7: =JILL!I7 -> 16.43 | J7: =JILL!J7 -> 23.12 | K7: =K4*K8 -> 28.322 | L7: =L4*L8 -> 33.27835 | M7: =M4*M8 -> 38.270103 | N7: =N4*N8 -> 43.053865 | O7: =O4*O8 -> 47.359252 | P7: =P4*P8 -> 50.911196 | Q7: =Q4*Q8 -> 53.456756
B8: % Revenue | C8: 0 | D8: 0 | F8: =F7/F4 -> 0.40700289 | G8: =G7/G4 -> 0.40378528 | H8: =H7/H4 -> 0.40314465 | I8: =I7/I4 -> 0.36349558 | J8: =J7/J4 -> 0.38469218 | K8: =J8+$C8 -> 0.38469218 | L8: =K8+$C8 -> 0.38469218 | M8: =L8+$D8 -> 0.38469218 | N8: =M8+$D8 -> 0.38469218 | O8: =N8+$D8 -> 0.38469218 | P8: =O8+$D8 -> 0.38469218 | Q8: =P8+$D8 -> 0.38469218
B10: GROSS PROFIT | F10: =F4-F7 -> 13.759051 | G10: =G4-G7 -> 16.157419 | H10: =H4-H7 -> 18.98 | I10: =I4-I7 -> 28.77 | J10: =J4-J7 -> 36.98 | K10: =K4-K7 -> 45.3005 | L10: =L4-L7 -> 53.228088 | M10: =M4-M7 -> 61.212301 | ... Q10: =Q4-Q7 -> 85.503063
B11: % Margin | F11: =F10/F4 -> 0.59299711 | G11: =G10/G4 -> 0.59621472 | H11: =H10/H4 -> 0.59685535 | I11: =I10/I4 -> 0.63650442 | J11: =J10/J4 -> 0.61530782 | K11: =K10/K4 -> 0.61530782 | L11: =L10/L4 -> 0.61530782 | M11: =M10/M4 -> 0.61530782 | ... Q11: =Q10/Q4 -> 0.61530782
B13: OPEX: | J13: `
B14: S&M | F14: ='mgmt '!I65+'mgmt '!I64 -> 7.727007 | G14: =JILL!G14 -> 7.614628 | H14: =JILL!H14 -> 9.19 | I14: =JILL!I14 -> 13 | J14: =JILL!J14 -> 14.96 | K14: =K$4*K21 -> 16.85355 | L14: =L$4*L21 -> 18.072792 | M14: =M$4*M21 -> 20.286299 | N14: =N$4*N21 -> 22.262498 | O14: =O$4*O21 -> 23.873201 | P14: =P$4*P21 -> 25.001977 | Q14: =Q$4*Q21 -> 25.557277
B15: R&D | F15: ='mgmt '!I63+'mgmt '!I66+'mgmt '!I67+'mgmt '!I69 -> 7.308554 | G15: =JILL!G15 -> 6.992441 | H15: =JILL!H15 -> 0.24 | I15: =JILL!I15 -> 0.24 | J15: =JILL!J15 -> 0.24 | K15: =K$4*K22 -> 7.36225 | L15: =L$4*L22 -> 8.6506438 | M15: =M$4*M22 -> 8.9534163 | N15: =N$4*N22 -> 8.9534163 | O15: =O$4*O22 -> 8.6176632 | P15: =P$4*P22 -> 7.9405611 | Q15: =Q$4*Q22 -> 6.9479909
B16: G&A | F16: ='mgmt '!I70-('Standalone Case'!F14+'Standalone Case'!F15) -> 0.11225 | G16: =JILL!G16 -> 0.018178 | H16: =JILL!H16 -> 10.35 | I16: =JILL!I16 -> 11.53 | J16: =JILL!J16 -> 13.06 | K16: =K$4*K23 -> 15.446331 | L16: =L$4*L23 -> 17.500641 | M16: =M$4*M23 -> 19.877031 | N16: =N$4*N23 -> 22.081866 | O16: =O$4*O23 -> 23.982279 | P16: =P$4*P23 -> 25.450093 | Q16: =Q$4*Q23 -> 26.375198
B17: OPEX | F17: =SUM(F14:F16) -> 15.147811 | G17: =SUM(G14:G16) -> 14.625247 | H17: =SUM(H14:H16) -> 19.78 | I17: =SUM(I14:I16) -> 24.77 | J17: =SUM(J14:J16) -> 28.26 | K17: =SUM(K14:K16) -> 39.662131 | L17: =SUM(L14:L16) -> 44.224077 | M17: =SUM(M14:M16) -> 49.116747 | ... Q17: =SUM(Q14:Q16) -> 58.880466
B18: % Revenue | F18: =F17/F4 -> 0.65285085 | G18: =G17/G4 -> 0.53967701 | H18: =H17/H4 -> 0.62201258 | I18: =I17/I4 -> 0.54800885 | J18: =J17/J4 -> 0.47021631 | K18: =K17/K4 -> 0.53872296 | L18: =L17/L4 -> 0.51122296 | M18: =M17/M4 -> 0.49372296 | ... Q18: =Q17/Q4 -> 0.42372296
B20: OPEX % Revenue:
B21: S&M | C21: -0.02 | D21: -0.005 | F21: =F14/F$4 -> 0.3330239 | G21: =G14/G$4 -> 0.28098258 | H21: =H14/H$4 -> 0.28899371 | I21: =I14/I$4 -> 0.28761062 | J21: =J14/J$4 -> 0.24891847 | K21: =J21+$C21 -> 0.22891847 | L21: =K21+$C21 -> 0.20891847 | M21: =L21+$D21 -> 0.20391847 | N21: =M21+$D21 -> 0.19891847 | O21: =N21+$D21 -> 0.19391847 | P21: =O21+$D21 -> 0.18891847 | Q21: =P21+$D21 -> 0.18391847
B22: R&D | D22: -0.01 | F22: =F15/F$4 -> 0.31498912 | G22: =G15/G$4 -> 0.25802365 | H22: =H15/H$4 -> 0.0075471698 | I22: =I15/I$4 -> 0.0053097345 | J22: =J15/J$4 -> 0.0039933444 | K22: 0.1 | L22: 0.1 | M22: =L22+$D22 -> 0.09 | N22: =M22+$D22 -> 0.08 | O22: =N22+$D22 -> 0.07 | P22: =O22+$D22 -> 0.06 | Q22: =P22+$D22 -> 0.05
B23: G&A | C23: -0.0075 | D23: -0.0025 | F23: =F16/F$4 -> 0.0048378282 | G23: =G16/G$4 -> 0.00067077491 | H23: =H16/H$4 -> 0.3254717 | I23: =I16/I$4 -> 0.2550885 | J23: =J16/J$4 -> 0.21730449 | K23: =J23+$C23 -> 0.20980449 | L23: =K23+$C23 -> 0.20230449 | M23: =L23+$D23 -> 0.19980449 | N23: =M23+$D23 -> 0.19730449 | O23: =N23+$D23 -> 0.19480449 | P23: =O23+$D23 -> 0.19230449 | Q23: =P23+$D23 -> 0.18980449
B24: Total Opex % | F24: =SUM(F21:F23) -> 0.65285085 | G24: =SUM(G21:G23) -> 0.53967701 | H24: =SUM(H21:H23) -> 0.62201258 | I24: =SUM(I21:I23) -> 0.54800885 | J24: =SUM(J21:J23) -> 0.47021631 | K24: =SUM(K21:K23) -> 0.53872296 | L24: =SUM(L21:L23) -> 0.51122296 | M24: =SUM(M21:M23) -> 0.49372296 | ... Q24: =SUM(Q21:Q23) -> 0.42372296
B26: EBIT | F26: =F10-F17 -> -1.3887601 | G26: =G10-G17 -> 1.532172 | H26: =H10-H17 -> -0.8 | I26: =I10-I17 -> 4 | J26: =J10-J17 -> 8.72 | K26: =K10-K17 -> 5.6383687 | L26: =L10-L17 -> 9.0040103 | M26: =M10-M17 -> 12.095554 | ... Q26: =Q10-Q17 -> 26.622597
B27: % Margin | F27: =F26/F4 -> -0.059853744 | G27: =G26/G4 -> 0.056537712 | H27: =H26/H4 -> -0.025157233 | I27: =I26/I4 -> 0.088495575 | J27: =J26/J4 -> 0.14509151 | K27: =K26/K4 -> 0.076584859 | L27: =L26/L4 -> 0.10408486 | M27: =M26/M4 -> 0.12158486 | ... Q27: =Q26/Q4 -> 0.19158486
B29: D&A | F29: ='mgmt '!I86 -> 0.99483639 | G29: =JILL!G29 -> 2.2 | H29: =JILL!H29 -> 1.28 | I29: =JILL!I29 -> 1.3 | J29: =JILL!J29 -> 2.8 | K29: =K4*K30 -> 3.681125 | L29: =L4*L30 -> 4.3253219 | M29: =M35 -> 5.670497 | N29: =N35 -> 6.043556 | O29: =O35 -> 6.2785832 | P29: =P35 -> 6.3524489 | Q29: =Q35 -> 6.2531918
B30: % Revenue | C30: 0.05 | D30: =D36 -> 0.003 | F30: =F29/F4 -> 0.042876148 | G30: =G29/G4 -> 0.081180812 | H30: =H29/H4 -> 0.040251572 | I30: =I29/I4 -> 0.028761062 | J30: =J29/J4 -> 0.046589018 | K30: =C30 -> 0.05 | L30: =K30 -> 0.05 | M30: =M29/M4 -> 0.057 | N30: =N29/N4 -> 0.054 | O30: =O29/O4 -> 0.051 | P30: =P29/P4 -> 0.048 | Q30: =Q29/Q4 -> 0.045
B32: EBITDA | F32: =F26+F29 -> -0.3939237 | G32: =G26+G29 -> 3.732172 | H32: =H26+H29 -> 0.48 | I32: =I26+I29 -> 5.3 | J32: =J26+J29 -> 11.52 | K32: =K26+K29 -> 9.3194937 | L32: =L26+L29 -> 13.329332 | M32: =M26+M29 -> 17.766051 | ... Q32: =Q26+Q29 -> 32.875789
B33: % Margin | F33: =F32/F4 -> -0.016977596 | G33: =G32/G4 -> 0.13771852 | H33: =H32/H4 -> 0.01509434 | I33: =I32/I4 -> 0.11725664 | J33: =J32/J4 -> 0.19168053 | K33: =K32/K4 -> 0.12658486 | L33: =L32/L4 -> 0.15408486 | M33: =M32/M4 -> 0.17858486 | ... Q33: =Q32/Q4 -> 0.23658486
B35: Capex (HST) | F35: 0 | G35: =JILL!G35 -> 1 | H35: =JILL!H35 -> 1.28 | I35: =JILL!I35 -> 1.3 | J35: =JILL!J35 -> 2.8 | K35: =K4*K36 -> 4.41735 | L35: =L4*L36 -> 5.1903863 | M35: =M4*M36 -> 5.670497 | N35: =N4*N36 -> 6.043556 | O35: =O4*O36 -> 6.2785832 | P35: =P4*P36 -> 6.3524489 | Q35: =Q4*Q36 -> 6.2531918
B36: % Revenue | C36: 0.06 | D36: 0.003 | F36: =F35/F4 -> 0 | G36: =G35/G4 -> 0.036900369 | H36: =H35/H4 -> 0.040251572 | I36: =I35/I4 -> 0.028761062 | J36: =J35/J4 -> 0.046589018 | K36: =C36 -> 0.06 | L36: =K36 -> 0.06 | M36: =L36-$D$36 -> 0.057 | N36: =M36-$D$36 -> 0.054 | O36: =N36-$D$36 -> 0.051 | P36: =O36-$D$36 -> 0.048 | Q36: =P36-$D$36 -> 0.045
A39: DCF
G40: PERIOD | H40: 1 | I40: 2 | J40: 3 | K40: 4 | L40: 5 | M40: =L40+1 -> 6 | N40: =M40+1 -> 7 | O40: =N40+1 -> 8 | P40: =O40+1 -> 9 | Q40: =P40+1 -> 10
B41: NWC | C41: 0.05 | D41: =C41 -> 0.05 | G41: =G4*$C$41 -> 1.355 | H41: =H4*$C$41 -> 1.59 | I41: =I4*$C$41 -> 2.26 | J41: =J4*$C$41 -> 3.005 | K41: =K4*$C$41 -> 3.681125 | L41: =L4*$C$41 -> 4.3253219 | M41: =M4*$D$41 -> 4.9741202 | N41: =N4*$D$41 -> 5.5958852 | O41: =O4*$D$41 -> 6.1554737 | P41: =P4*$D$41 -> 6.6171342 | Q41: =Q4*$D$41 -> 6.9479909
B42: Change in NWC | H42: =H41-G41 -> 0.235 | I42: =I41-H41 -> 0.67 | J42: =J41-I41 -> 0.745 | K42: =K41-J41 -> 0.676125 | L42: =L41-K41 -> 0.64419688 | M42: =M41-L41 -> 0.64879828 | N42: =N41-M41 -> 0.62176502 | O42: =O41-N41 -> 0.55958852 | ... Q42: =Q41-P41 -> 0.33085671
B44: EBIT | H44: =H26 -> -0.8 | I44: =I26 -> 4 | J44: =J26 -> 8.72 | K44: =K26 -> 5.6383687 | L44: =L26 -> 9.0040103 | M44: =M26 -> 12.095554 | N44: =N26 -> 15.566058 | O44: =O26 -> 19.27708 | ... Q44: =Q26 -> 26.622597
B45: - Taxes | C45: 0.2 | H45: 0 | I45: =-I44*$C$45 -> -0.8 | J45: =-J44*$C$45 -> -1.744 | K45: =-K44*$C$45 -> -1.1276738 | L45: =-L44*$C$45 -> -1.8008021 | M45: =-M44*$C$45 -> -2.4191108 | N45: =-N44*$C$45 -> -3.1132116 | O45: =-O44*$C$45 -> -3.8554159 | P45: =-P44*$C$45 -> -4.6077715 | Q45: =-Q44*$C$45 -> -5.3245194
B46: +NOL | C46: 1 | H46: =IF(-H45<=$C$46,-H45,($C$46)) -> 0 | I46: =IF(-I45<=$C$46,-I45,($C$46)) -> 0.8 | J46: =IF(-J45<=$C$46,-J45,($C$46)) -> 1 | K46: =IF(-K45<=$C$46,-K45,($C$46)) -> 1 | L46: =IF(-L45<=$C$46,-L45,($C$46)) -> 1 | M46: =IF(-M45<=$C$46,-M45,($C$46)) -> 1 | N46: =IF(-N45<=$C$46,-N45,($C$46)) -> 1 | O46: =IF(-O45<=$C$46,-O45,($C$46)) -> 1 | ... Q46: =IF(-Q45<=$C$46,-Q45,($C$46)) -> 1
B47: - Capex | H47: =-H35 -> -1.28 | I47: =-I35 -> -1.3 | J47: =-J35 -> -2.8 | K47: =-K35 -> -4.41735 | L47: =-L35 -> -5.1903863 | M47: =-M35 -> -5.670497 | N47: =-N35 -> -6.043556 | O47: =-O35 -> -6.2785832 | ... Q47: =-Q35 -> -6.2531918
B48: + D&A | H48: =H29 -> 1.28 | I48: =I29 -> 1.3 | J48: =J29 -> 2.8 | K48: =K29 -> 3.681125 | L48: =L29 -> 4.3253219 | M48: =M29 -> 5.670497 | N48: =N29 -> 6.043556 | O48: =O29 -> 6.2785832 | ... Q48: =Q29 -> 6.2531918
B49: +/- Changes in NWC | H49: =H42 -> 0.235 | I49: =I42 -> 0.67 | J49: =J42 -> 0.745 | K49: =K42 -> 0.676125 | L49: =L42 -> 0.64419688 | M49: =M42 -> 0.64879828 | N49: =N42 -> 0.62176502 | O49: =O42 -> 0.55958852 | ... Q49: =Q42 -> 0.33085671
B50: Free Cash Flow | H50: =SUM(H44:H49) -> -0.565 | I50: =SUM(I44:I49) -> 4.67 | J50: =SUM(J44:J49) -> 8.721 | K50: =SUM(K44:K49) -> 5.450595 | L50: =SUM(L44:L49) -> 7.9823407 | M50: =SUM(M44:M49) -> 11.325241 | N50: =SUM(N44:N49) -> 14.074611 | O50: =SUM(O44:O49) -> 16.981252 | ... Q50: =SUM(Q44:Q49) -> 22.628934
B52: Period # | H52: 1 | I52: =H52+1 -> 2 | J52: =I52+1 -> 3 | K52: =J52+1 -> 4 | L52: =K52+1 -> 5 | M52: =L52+1 -> 6 | N52: =M52+1 -> 7 | O52: =N52+1 -> 8 | P52: =O52+1 -> 9 | Q52: =P52+1 -> 10 | R52: TV
B53: Discount Factor | C53: 0.18 | H53: =1/((1+$C$53)^H52) -> 0.84745763 | I53: =1/((1+$C$53)^I52) -> 0.71818443 | J53: =1/((1+$C$53)^J52) -> 0.60863087 | K53: =1/((1+$C$53)^K52) -> 0.51578888 | L53: =1/((1+$C$53)^L52) -> 0.43710922 | M53: =1/((1+$C$53)^M52) -> 0.37043154 | N53: =1/((1+$C$53)^N52) -> 0.31392503 | O53: =1/((1+$C$53)^O52) -> 0.26603816 | ... Q53: =1/((1+$C$53)^Q52) -> 0.19106447 | R53: =Q53 -> 0.19106447
...

Sheet SYNERGY CASE 
A1: SYNERGY BASE CASE
F2: 2017A | G2: 2018A | H2: 2019 | I2: 2020 | J2: 2021 | K2: 2022 | L2: =K2+1 -> 2023 | M2: =L2+1 -> 2024 | N2: =M2+1 -> 2025 | O2: =N2+1 -> 2026 | P2: =O2+1 -> 2027 | Q2: =P2+1 -> 2028
B4: Net Revenue | F4: 23.20256 | G4: =JILL!G4 -> 27.1 | H4: =JILL!L4 -> 33.8 | I4: =JILL!M4 -> 59.73 | J4: =JILL!N4 -> 80.5 | K4: =J4*(1+K5) -> 98.6125 | L4: =K4*(1+L5) -> 115.86969 | M4: =L4*(1+M5) -> 133.25014 | N4: =M4*(1+N5) -> 149.90641 | O4: =N4*(1+O5) -> 164.89705 | P4: =O4*(1+P5) -> 177.26433 | Q4: =P4*(1+Q5) -> 186.12754
B5: Growth % | D5: 0.025 | F5: ='mgmt '!I25 -> 0.18757834 | G5: =G4/F4-1 -> 0.16797457 | H5: =H4/G4-1 -> 0.24723247 | I5: =I4/H4-1 -> 0.76715976 | J5: =J4/I4-1 -> 0.34773146 | K5: 0.225 | L5: 0.175 | M5: 0.15 | N5: =M5-$D$5 -> 0.125 | O5: =N5-$D$5 -> 0.1 | P5: =O5-$D$5 -> 0.075 | Q5: =P5-$D$5 -> 0.05
B7: COGS | F7: ='mgmt '!I48 -> 9.4435091 | G7: =JILL!G7 -> 10.942581 | H7: =JILL!L7 -> 13.6 | I7: =JILL!M7 -> 22.06 | J7: =JILL!N7 -> 31.1 | K7: =K4*K8 -> 38.0975 | L7: =L4*L8 -> 44.764562 | M7: =M4*M8 -> 51.479247 | N7: =N4*N8 -> 57.914153 | O7: =O4*O8 -> 63.705568 | P7: =P4*P8 -> 68.483486 | Q7: =Q4*Q8 -> 71.90766
B8: % Revenue | C8: 0 | D8: 0 | F8: =F7/F4 -> 0.40700289 | G8: =G7/G4 -> 0.40378528 | H8: =H7/H4 -> 0.40236686 | I8: =I7/I4 -> 0.36932865 | J8: =J7/J4 -> 0.3863354 | K8: =J8+$C8 -> 0.3863354 | L8: =K8+$C8 -> 0.3863354 | M8: =L8+$D8 -> 0.3863354 | N8: =M8+$D8 -> 0.3863354 | O8: =N8+$D8 -> 0.3863354 | P8: =O8+$D8 -> 0.3863354 | Q8: =P8+$D8 -> 0.3863354
B10: GROSS PROFIT | F10: =F4-F7 -> 13.759051 | G10: =G4-G7 -> 16.157419 | H10: =H4-H7 -> 20.2 | I10: =I4-I7 -> 37.67 | J10: =J4-J7 -> 49.4 | K10: =K4-K7 -> 60.515 | L10: =L4-L7 -> 71.105125 | M10: =M4-M7 -> 81.770894 | ... Q10: =Q4-Q7 -> 114.21988
B11: % Margin | F11: =F10/F4 -> 0.59299711 | G11: =G10/G4 -> 0.59621472 | H11: =H10/H4 -> 0.59763314 | I11: =I10/I4 -> 0.63067135 | J11: =J10/J4 -> 0.6136646 | K11: =K10/K4 -> 0.6136646 | L11: =L10/L4 -> 0.6136646 | M11: =M10/M4 -> 0.6136646 | ... Q11: =Q10/Q4 -> 0.6136646
B13: OPEX: | J13: `
B14: S&M | F14: ='mgmt '!I65+'mgmt '!I64 -> 7.727007 | G14: =JILL!G14 -> 7.614628 | H14: =JILL!L14 -> 9.9 | I14: =JILL!M14 -> 14.3 | J14: =JILL!N14 -> 16.4 | K14: =K$4*K21 -> 18.11775 | L14: =L$4*L21 -> 18.970962 | M14: =M$4*M21 -> 21.150356 | N14: =N$4*N21 -> 23.044619 | O14: =O$4*O21 -> 24.524595 | P14: =P$4*P21 -> 25.477618 | Q14: =Q$4*Q21 -> 25.820861
B15: R&D | F15: ='mgmt '!I63+'mgmt '!I66+'mgmt '!I67+'mgmt '!I69 -> 7.308554 | G15: =JILL!G15 -> 6.992441 | H15: =JILL!L15 -> 1.7 | I15: =JILL!M15 -> 3.4 | J15: =JILL!N15 -> 0.4 | K15: =K$4*K22 -> 9.86125 | L15: =L$4*L22 -> 11.586969 | M15: =M$4*M22 -> 11.992513 | N15: =N$4*N22 -> 11.992513 | O15: =O$4*O22 -> 11.542793 | P15: =P$4*P22 -> 10.63586 | Q15: =Q$4*Q22 -> 9.3063772
B16: G&A | F16: ='mgmt '!I70-('SYNERGY CASE '!F14+'SYNERGY CASE '!F15) -> 0.11225 | G16: =JILL!G16 -> 0.018178 | H16: =JILL!L16 -> 11.3 | I16: =JILL!M16 -> 13.6 | J16: =JILL!N16 -> 15.1 | K16: =K$4*K23 -> 17.757906 | L16: =L$4*L23 -> 19.996517 | M16: =M$4*M23 -> 22.662869 | N16: =N$4*N23 -> 25.120962 | O16: =O$4*O23 -> 27.220816 | P16: =P$4*P23 -> 28.819216 | Q16: =Q$4*Q23 -> 29.794858
B17: OPEX | F17: =SUM(F14:F16) -> 15.147811 | G17: =SUM(G14:G16) -> 14.625247 | H17: =SUM(H14:H16) -> 22.9 | I17: =SUM(I14:I16) -> 31.3 | J17: =SUM(J14:J16) -> 31.9 | K17: =SUM(K14:K16) -> 45.736906 | L17: =SUM(L14:L16) -> 50.554448 | M17: =SUM(M14:M16) -> 55.805738 | ... Q17: =SUM(Q14:Q16) -> 64.922097
B18: % Revenue | F18: =F17/F4 -> 0.65285085 | G18: =G17/G4 -> 0.53967701 | H18: =H17/H4 -> 0.67751479 | I18: =I17/I4 -> 0.52402478 | J18: =J17/J4 -> 0.39627329 | K18: =K17/K4 -> 0.46380435 | L18: =L17/L4 -> 0.43630435 | M18: =M17/M4 -> 0.41880435 | ... Q18: =Q17/Q4 -> 0.34880435
B20: OPEX % Revenue:
B21: S&M | C21: -0.02 | D21: -0.005 | F21: =F14/F$4 -> 0.3330239 | G21: =G14/G$4 -> 0.28098258 | H21: =H14/H$4 -> 0.29289941 | I21: =I14/I$4 -> 0.23941068 | J21: =J14/J$4 -> 0.20372671 | K21: =J21+$C21 -> 0.18372671 | L21: =K21+$C21 -> 0.16372671 | M21: =L21+$D21 -> 0.15872671 | N21: =M21+$D21 -> 0.15372671 | O21: =N21+$D21 -> 0.14872671 | P21: =O21+$D21 -> 0.14372671 | Q21: =P21+$D21 -> 0.13872671
B22: R&D | D22: -0.01 | F22: =F15/F$4 -> 0.31498912 | G22: =G15/G$4 -> 0.25802365 | H22: =H15/H$4 -> 0.050295858 | I22: =I15/I$4 -> 0.056922819 | J22: =J15/J$4 -> 0.0049689441 | K22: 0.1 | L22: 0.1 | M22: =L22+$D22 -> 0.09 | N22: =M22+$D22 -> 0.08 | O22: =N22+$D22 -> 0.07 | P22: =O22+$D22 -> 0.06 | Q22: =P22+$D22 -> 0.05
B23: G&A | C23: -0.0075 | D23: -0.0025 | F23: =F16/F$4 -> 0.0048378282 | G23: =G16/G$4 -> 0.00067077491 | H23: =H16/H$4 -> 0.33431953 | I23: =I16/I$4 -> 0.22769128 | J23: =J16/J$4 -> 0.18757764 | K23: =J23+$C23 -> 0.18007764 | L23: =K23+$C23 -> 0.17257764 | M23: =L23+$D23 -> 0.17007764 | N23: =M23+$D23 -> 0.16757764 | O23: =N23+$D23 -> 0.16507764 | P23: =O23+$D23 -> 0.16257764 | Q23: =P23+$D23 -> 0.16007764
B24: Total Opex % | F24: =SUM(F21:F23) -> 0.65285085 | G24: =SUM(G21:G23) -> 0.53967701 | H24: =SUM(H21:H23) -> 0.67751479 | I24: =SUM(I21:I23) -> 0.52402478 | J24: =SUM(J21:J23) -> 0.39627329 | K24: =SUM(K21:K23) -> 0.46380435 | L24: =SUM(L21:L23) -> 0.43630435 | M24: =SUM(M21:M23) -> 0.41880435 | ... Q24: =SUM(Q21:Q23) -> 0.34880435
B26: EBIT | F26: =F10-F17 -> -1.3887601 | G26: =G10-G17 -> 1.532172 | H26: =H10-H17 -> -2.7 | I26: =I10-I17 -> 6.37 | J26: =J10-J17 -> 17.5 | K26: =K10-K17 -> 14.778094 | L26: =L10-L17 -> 20.550677 | M26: =M10-M17 -> 25.965156 | ... Q26: =Q10-Q17 -> 49.297788
B27: % Margin | F27: =F26/F4 -> -0.059853744 | G27: =G26/G4 -> 0.056537712 | H27: =H26/H4 -> -0.079881657 | I27: =I26/I4 -> 0.10664658 | J27: =J26/J4 -> 0.2173913 | K27: =K26/K4 -> 0.14986025 | L27: =L26/L4 -> 0.17736025 | M27: =M26/M4 -> 0.19486025 | ... Q27: =Q26/Q4 -> 0.26486025
B29: D&A | F29: ='mgmt '!I86 -> 0.99483639 | G29: =JILL!G29 -> 2.2 | H29: =JILL!H29 -> 1.28 | I29: =JILL!I29 -> 1.3 | J29: =JILL!J29 -> 2.8 | K29: =K4*K30 -> 4.930625 | L29: =L4*L30 -> 5.7934844 | M29: =M35 -> 7.595258 | N29: =N35 -> 8.094946 | O29: =O35 -> 8.4097495 | P29: =P35 -> 8.5086877 | Q29: =Q35 -> 8.3757395
B30: % Revenue | C30: 0.05 | D30: =D36 -> 0.003 | F30: =F29/F4 -> 0.042876148 | G30: =G29/G4 -> 0.081180812 | H30: =H29/H4 -> 0.037869822 | I30: =I29/I4 -> 0.021764607 | J30: =J29/J4 -> 0.034782609 | K30: =C30 -> 0.05 | L30: =K30 -> 0.05 | M30: =M29/M4 -> 0.057 | N30: =N29/N4 -> 0.054 | O30: =O29/O4 -> 0.051 | P30: =P29/P4 -> 0.048 | Q30: =Q29/Q4 -> 0.045
B32: EBITDA | F32: =F26+F29 -> -0.3939237 | G32: =G26+G29 -> 3.732172 | H32: =H26+H29 -> -1.42 | I32: =I26+I29 -> 7.67 | J32: =J26+J29 -> 20.3 | K32: =K26+K29 -> 19.708719 | L32: =L26+L29 -> 26.344161 | M32: =M26+M29 -> 33.560414 | ... Q32: =Q26+Q29 -> 57.673527
B33: % Margin | F33: =F32/F4 -> -0.016977596 | G33: =G32/G4 -> 0.13771852 | H33: =H32/H4 -> -0.042011834 | I33: =I32/I4 -> 0.12841118 | J33: =J32/J4 -> 0.25217391 | K33: =K32/K4 -> 0.19986025 | L33: =L32/L4 -> 0.22736025 | M33: =M32/M4 -> 0.25186025 | ... Q33: =Q32/Q4 -> 0.30986025
B35: Capex (HST) | F35: 0 | G35: =JILL!G35 -> 1 | H35: =JILL!H35 -> 1.28 | I35: =JILL!I35 -> 1.3 | J35: =JILL!J35 -> 2.8 | K35: =K4*K36 -> 5.91675 | L35: =L4*L36 -> 6.9521812 | M35: =M4*M36 -> 7.595258 | N35: =N4*N36 -> 8.094946 | O35: =O4*O36 -> 8.4097495 | P35: =P4*P36 -> 8.5086877 | Q35: =Q4*Q36 -> 8.3757395
B36: % Revenue | C36: 0.06 | D36: 0.003 | F36: =F35/F4 -> 0 | G36: =G35/G4 -> 0.036900369 | H36: =H35/H4 -> 0.037869822 | I36: =I35/I4 -> 0.021764607 | J36: =J35/J4 -> 0.034782609 | K36: =C36 -> 0.06 | L36: =K36 -> 0.06 | M36: =L36-$D$36 -> 0.057 | N36: =M36-$D$36 -> 0.054 | O36: =N36-$D$36 -> 0.051 | P36: =O36-$D$36 -> 0.048 | Q36: =P36-$D$36 -> 0.045
A39: DCF
G40: PERIOD | H40: 1 | I40: 2 | J40: 3 | K40: 4 | L40: 5 | M40: =L40+1 -> 6 | N40: =M40+1 -> 7 | O40: =N40+1 -> 8 | P40: =O40+1 -> 9 | Q40: =P40+1 -> 10
B41: NWC | C41: 0.05 | D41: =C41 -> 0.05 | G41: =G4*$C$41 -> 1.355 | H41: =H4*$C$41 -> 1.69 | I41: =I4*$C$41 -> 2.9865 | J41: =J4*$C$41 -> 4.025 | K41: =K4*$C$41 -> 4.930625 | L41: =L4*$C$41 -> 5.7934844 | M41: =M4*$D$41 -> 6.662507 | N41: =N4*$D$41 -> 7.4953204 | O41: =O4*$D$41 -> 8.2448525 | P41: =P4*$D$41 -> 8.8632164 | Q41: =Q4*$D$41 -> 9.3063772
B42: Change in NWC | H42: =H41-G41 -> 0.335 | I42: =I41-H41 -> 1.2965 | J42: =J41-I41 -> 1.0385 | K42: =K41-J41 -> 0.905625 | L42: =L41-K41 -> 0.86285937 | M42: =M41-L41 -> 0.86902266 | N42: =N41-M41 -> 0.83281338 | O42: =O41-N41 -> 0.74953204 | ... Q42: =Q41-P41 -> 0.44316082
B44: EBIT | H44: =H26 -> -2.7 | I44: =I26 -> 6.37 | J44: =J26 -> 17.5 | K44: =K26 -> 14.778094 | L44: =L26 -> 20.550677 | M44: =M26 -> 25.965156 | N44: =N26 -> 31.834162 | O44: =O26 -> 37.903277 | ... Q44: =Q26 -> 49.297788
B45: - Taxes | C45: 0.2 | H45: 0 | I45: =-I44*$C$45 -> -1.274 | J45: =-J44*$C$45 -> -3.5 | K45: =-K44*$C$45 -> -2.9556188 | L45: =-L44*$C$45 -> -4.1101353 | M45: =-M44*$C$45 -> -5.1930311 | N45: =-N44*$C$45 -> -6.3668324 | O45: =-O44*$C$45 -> -7.5806553 | P45: =-P44*$C$45 -> -8.7696296 | Q45: =-Q44*$C$45 -> -9.8595575
B46: +NOL | C46: 1 | H46: =IF(-H45<=$C$46,-H45,($C$46)) -> 0 | I46: =IF(-I45<=$C$46,-I45,($C$46)) -> 1 | J46: =IF(-J45<=$C$46,-J45,($C$46)) -> 1 | K46: =IF(-K45<=$C$46,-K45,($C$46)) -> 1 | L46: =IF(-L45<=$C$46,-L45,($C$46)) -> 1 | M46: =IF(-M45<=$C$46,-M45,($C$46)) -> 1 | N46: =IF(-N45<=$C$46,-N45,($C$46)) -> 1 | O46: =IF(-O45<=$C$46,-O45,($C$46)) -> 1 | ... Q46: =IF(-Q45<=$C$46,-Q45,($C$46)) -> 1
B47: - Capex | H47: =-H35 -> -1.28 | I47: =-I35 -> -1.3 | J47: =-J35 -> -2.8 | K47: =-K35 -> -5.91675 | L47: =-L35 -> -6.9521812 | M47: =-M35 -> -7.595258 | N47: =-N35 -> -8.094946 | O47: =-O35 -> -8.4097495 | ... Q47: =-Q35 -> -8.3757395
B48: + D&A | H48: =H29 -> 1.28 | I48: =I29 -> 1.3 | J48: =J29 -> 2.8 | K48: =K29 -> 4.930625 | L48: =L29 -> 5.7934844 | M48: =M29 -> 7.595258 | N48: =N29 -> 8.094946 | O48: =O29 -> 8.4097495 | ... Q48: =Q29 -> 8.3757395
B49: +/- Changes in NWC | H49: =H42 -> 0.335 | I49: =I42 -> 1.2965 | J49: =J42 -> 1.0385 | K49: =K42 -> 0.905625 | L49: =L42 -> 0.86285937 | M49: =M42 -> 0.86902266 | N49: =N42 -> 0.83281338 | O49: =O42 -> 0.74953204 | ... Q49: =Q42 -> 0.44316082
B50: Free Cash Flow | H50: =SUM(H44:H49) -> -2.365 | I50: =SUM(I44:I49) -> 7.3925 | J50: =SUM(J44:J49) -> 16.0385 | K50: =SUM(K44:K49) -> 12.741975 | L50: =SUM(L44:L49) -> 17.144704 | M50: =SUM(M44:M49) -> 22.641147 | N50: =SUM(N44:N49) -> 27.300143 | O50: =SUM(O44:O49) -> 32.072153 | ... Q50: =SUM(Q44:Q49) -> 40.881391
B52: Period # | H52: 1 | I52: =H52+1 -> 2 | J52: =I52+1 -> 3 | K52: =J52+1 -> 4 | L52: =K52+1 -> 5 | M52: =L52+1 -> 6 | N52: =M52+1 -> 7 | O52: =N52+1 -> 8 | P52: =O52+1 -> 9 | Q52: =P52+1 -> 10 | R52: TV
B53: Discount Factor | C53: 0.18 | H53: =1/((1+$C$53)^H52) -> 0.84745763 | I53: =1/((1+$C$53)^I52) -> 0.71818443 | J53: =1/((1+$C$53)^J52) -> 0.60863087 | K53: =1/((1+$C$53)^K52) -> 0.51578888 | L53: =1/((1+$C$53)^L52) -> 0.43710922 | M53: =1/((1+$C$53)^M52) -> 0.37043154 | N53: =1/((1+$C$53)^N52) -> 0.31392503 | O53: =1/((1+$C$53)^O52) -> 0.26603816 | ... Q53: =1/((1+$C$53)^Q52) -> 0.19106447 | R53: =Q53 -> 0.19106447
...

Sheet BENCHMARKS
B1: Conditional Formatting: | L1: Low | M1: High | N1: Check Mark
K2: Revenue | L2: 20000 | M2: 60000
A4: COMPARABLE PUBLIC COMP BENCHMARK FINANCIAL ANALYSIS
A5: $ in thousands (source: PitchBook retrieved April 2019)
S6: 3 YR CAGR
J7: =K7-1 -> 2011 | K7: =L7-1 -> 2012 | L7: =M7-1 -> 2013 | M7: =N7-1 -> 2014 | N7: =O7-1 -> 2015 | O7: =P7-1 -> 2016 | P7: =Q7-1 -> 2017 | Q7: 2018 | S7: 2015 -2018
A8: 1. REVENUE
B9: 1. REVENUE
B10: BioTelemetry | J10: ='BIO - Income Statement (2)'!U12 -> 119022 | K10: ='BIO - Income Statement (2)'!V12 -> 111494 | L10: ='BIO - Income Statement (2)'!W12 -> 129501 | M10: ='BIO - Income Statement (2)'!X12 -> 166578 | N10: ='BIO - Income Statement (2)'!Y12 -> 178513 | O10: ='BIO - Income Statement (2)'!Z12 -> 198229 | P10: ='BIO - Income Statement (2)'!AA12 -> 273175 | Q10: ='BIO - Income Statement (2)'!AB12 -> 389373 | S10: =(Q10/N10)^(1/3)-1 -> 0.29687662
B11: Inogen | J11: ='inogen P&L'!M12 -> 30099 | K11: ='inogen P&L'!N12 -> 48576 | L11: ='inogen P&L'!O12 -> 75443 | M11: ='inogen P&L'!P12 -> 112537 | N11: ='inogen P&L'!Q12 -> 159005 | O11: ='inogen P&L'!R12 -> 202829 | P11: ='inogen P&L'!S12 -> 249438 | Q11: ='inogen P&L'!T12 -> 358111 | S11: =(Q11/N11)^(1/3)-1 -> 0.31079757
B12: iRhythm | M12: ='irhy - P&L'!M12 -> 21749 | N12: ='irhy - P&L'!N12 -> 36140 | O12: ='irhy - P&L'!O12 -> 64072 | P12: ='irhy - P&L'!P12 -> 98509 | Q12: ='irhy - P&L'!Q12 -> 147293 | S12: =(Q12/N12)^(1/3)-1 -> 0.59734228
B14: 1.A REVENUE GROWTH:
B15: BioTelemetry | K15: =K10/J10-1 -> -0.063248811 | L15: =L10/K10-1 -> 0.16150645 | M15: =M10/L10-1 -> 0.28630667 | N15: =N10/M10-1 -> 0.071648117 | O15: =O10/N10-1 -> 0.11044574 | P15: =P10/O10-1 -> 0.37807788 | Q15: =Q10/P10-1 -> 0.42536103
B16: Inogen | K16: =K11/J11-1 -> 0.61387422 | L16: =L11/K11-1 -> 0.55309206 | M16: =M11/L11-1 -> 0.49168246 | N16: =N11/M11-1 -> 0.41291309 | O16: =O11/N11-1 -> 0.27561397 | P16: =P11/O11-1 -> 0.22979456 | Q16: =Q11/P11-1 -> 0.43567139
B17: iRhythm | K17: NA | L17: NA | M17: NA | N17: =N12/M12-1 -> 0.66168559 | O17: =O12/N12-1 -> 0.77288323 | P17: =P12/O12-1 -> 0.53747347 | Q17: =Q12/P12-1 -> 0.49522379
C19: 1.B REVENUE GROWTH ANALYTICS:
C20: 75th Percentile | K20: =PERCENTILE(K15:K17, 0.75) -> 0.44459346 | L20: =PERCENTILE(L15:L17, 0.75) -> 0.45519566 | M20: =PERCENTILE(M15:M17, 0.75) -> 0.44033851 | N20: =PERCENTILE(N15:N17, 0.75) -> 0.53729934 | O20: =PERCENTILE(O15:O17, 0.75) -> 0.5242486 | P20: =PERCENTILE(P15:P17, 0.75) -> 0.45777567 | Q20: =PERCENTILE(Q15:Q17, 0.75) -> 0.46544759 | S20: =PERCENTILE(S10:S12, 0.75) -> 0.45406992
C21: Median | K21: =MEDIAN(K15:K17) -> 0.2753127 | L21: =MEDIAN(L15:L17) -> 0.35729926 | M21: =MEDIAN(M15:M17) -> 0.38899457 | N21: =MEDIAN(N15:N17) -> 0.41291309 | O21: =MEDIAN(O15:O17) -> 0.27561397 | P21: =MEDIAN(P15:P17) -> 0.37807788 | Q21: =MEDIAN(Q15:Q17) -> 0.43567139 | S21: =MEDIAN(S10:S12) -> 0.31079757
C22: 25th Percentile | K22: =PERCENTILE(K15:K17, 0.25) -> 0.10603195 | L22: =PERCENTILE(L15:L17, 0.25) -> 0.25940285 | M22: =PERCENTILE(M15:M17, 0.25) -> 0.33765062 | N22: =PERCENTILE(N15:N17, 0.25) -> 0.2422806 | O22: =PERCENTILE(O15:O17, 0.25) -> 0.19302986 | P22: =PERCENTILE(P15:P17, 0.25) -> 0.30393622 | Q22: =PERCENTILE(Q15:Q17, 0.25) -> 0.43051621 | S22: =PERCENTILE(S10:S12, 0.25) -> 0.30383709
B24: Revenue Growth YoY Change %
B25: BioTelemetry | L25: =L15-K15 -> 0.22475526 | M25: =M15-L15 -> 0.12480022 | N25: =N15-M15 -> -0.21465855 | O25: =O15-N15 -> 0.038797621 | P25: =P15-O15 -> 0.26763214 | Q25: =Q15-P15 -> 0.047283153
B26: Inogen | L26: =L16-K16 -> -0.060782153 | M26: =M16-L16 -> -0.0614096 | N26: =N16-M16 -> -0.078769376 | O26: =O16-N16 -> -0.13729911 | P26: =P16-O16 -> -0.045819418 | Q26: =Q16-P16 -> 0.20587683
B27: iRhythm | M27: NA | N27: NM | O27: =O17-N17 -> 0.11119764 | P27: =P17-O17 -> -0.23540976 | Q27: =Q17-P17 -> -0.042249681
B29: COGS:
B30: BioTelemetry | J30: ='BIO - Income Statement (2)'!U15 -> 49076 | K30: ='BIO - Income Statement (2)'!V15 -> 45593 | L30: ='BIO - Income Statement (2)'!W15 -> 50431 | M30: ='BIO - Income Statement (2)'!X15 -> 73114 | N30: ='BIO - Income Statement (2)'!Y15 -> 71956 | O30: ='BIO - Income Statement (2)'!Z15 -> 78882 | P30: ='BIO - Income Statement (2)'!AA15 -> 114406 | Q30: ='BIO - Income Statement (2)'!AB15 -> 148986 | S30: =(Q30/M30)^(1/3)-1 -> 0.26779287
B31: Inogen | K31: ='inogen P&L'!N18 -> 24627 | L31: ='inogen P&L'!O18 -> 36452 | M31: ='inogen P&L'!P18 -> 57020 | N31: ='inogen P&L'!Q18 -> 82747 | O31: ='inogen P&L'!R18 -> 105519 | P31: ='inogen P&L'!S18 -> 128201 | Q31: ='inogen P&L'!T18 -> 179531 | S31: =(Q31/M31)^(1/3)-1 -> 0.4656741
B32: iRhythm | M32: ='irhy - P&L'!M14 -> 10591 | N32: ='irhy - P&L'!N14 -> 14700 | O32: ='irhy - P&L'!O14 -> 20883 | P32: ='irhy - P&L'!P14 -> 27708 | Q32: ='irhy - P&L'!Q14 -> 38579 | S32: =(Q32/M32)^(1/3)-1 -> 0.53864347
B34: Gross Profit:
B35: BioTelemetry | J35: =J10-J30 -> 69946 | K35: =K10-K30 -> 65901 | L35: =L10-L30 -> 79070 | M35: =M10-M30 -> 93464 | N35: =N10-N30 -> 106557 | O35: =O10-O30 -> 119347 | P35: =P10-P30 -> 158769 | Q35: =Q10-Q30 -> 240387
B36: Inogen | J36: ='Inogen - Key Metrics'!L12 | K36: =K11-K31 -> 23949 | L36: =L11-L31 -> 38991 | M36: =M11-M31 -> 55517 | N36: =N11-N31 -> 76258 | O36: =O11-O31 -> 97310 | P36: =P11-P31 -> 121237 | Q36: =Q11-Q31 -> 178580
B37: iRhythm | M37: =M12-M32 -> 11158 | N37: =N12-N32 -> 21440 | O37: =O12-O32 -> 43189 | P37: =P12-P32 -> 70801 | Q37: =Q12-Q32 -> 108714
B39: Gross Margin %:
B40: BioTelemetry | J40: =J35/J10 -> 0.58767287 | K40: =K35/K10 -> 0.59107217 | L40: =L35/L10 -> 0.61057444 | M40: =M35/M10 -> 0.5610825 | N40: =N35/N10 -> 0.59691451 | O40: =O35/O10 -> 0.6020663 | P40: =P35/P10 -> 0.58119887 | Q40: =Q35/Q10 -> 0.61736946
B41: Inogen | K41: =K36/K11 -> 0.49302125 | L41: =L36/L11 -> 0.51682727 | M41: =M36/M11 -> 0.4933222 | N41: =N36/N11 -> 0.47959498 | O41: =O36/O11 -> 0.47976374 | P41: =P36/P11 -> 0.48604062 | Q41: =Q36/Q11 -> 0.4986722
B42: iRhythm | M42: =M37/M12 -> 0.51303508 | N42: =N37/N12 -> 0.59324848 | O42: =O37/O12 -> 0.6740698 | P42: =P37/P12 -> 0.71872621 | Q42: =Q37/Q12 -> 0.73807988
B44: 75th Percentile | K44: =PERCENTILE(K40:K42, 0.75) -> 0.56655944 | L44: =PERCENTILE(L40:L42, 0.75) -> 0.58713765 | M44: =PERCENTILE(M40:M42, 0.75) -> 0.53705879 | N44: =PERCENTILE(N40:N42, 0.75) -> 0.59508149 | O44: =PERCENTILE(O40:O42, 0.75) -> 0.63806805 | P44: =PERCENTILE(P40:P42, 0.75) -> 0.64996254 | Q44: =PERCENTILE(Q40:Q42, 0.75) -> 0.67772467
B45: Median | K45: =MEDIAN(K40:K42) -> 0.54204671 | L45: =MEDIAN(L40:L42) -> 0.56370085 | M45: =MEDIAN(M40:M42) -> 0.51303508 | N45: =MEDIAN(N40:N42) -> 0.59324848 | O45: =MEDIAN(O40:O42) -> 0.6020663 | P45: =MEDIAN(P40:P42) -> 0.58119887 | Q45: =MEDIAN(Q40:Q42) -> 0.61736946
B46: 25th Percentile | K46: =PERCENTILE(K40:K42, 0.25) -> 0.51753398 | L46: =PERCENTILE(L40:L42, 0.25) -> 0.54026406 | M46: =PERCENTILE(M40:M42, 0.25) -> 0.50317864 | N46: =PERCENTILE(N40:N42, 0.25) -> 0.53642173 | O46: =PERCENTILE(O40:O42, 0.25) -> 0.54091502 | P46: =PERCENTILE(P40:P42, 0.25) -> 0.53361974 | Q46: =PERCENTILE(Q40:Q42, 0.25) -> 0.55802083
B48: OPEX:
B50: S&M:
...

Sheet Synergy Base Case - old
A1: SYNERGY BASE CASE
F2: 2017A | G2: 2018A | H2: 2019 | I2: 2020 | J2: 2021 | K2: 2022 | L2: =K2+1 -> 2023 | M2: =L2+1 -> 2024 | N2: =M2+1 -> 2025 | O2: =N2+1 -> 2026 | P2: =O2+1 -> 2027 | Q2: =P2+1 -> 2028
B4: Net Revenue | F4: 23.20256 | G4: ='Standalone Case'!G4 -> 27.1 | H4: =JILL!L4 -> 33.8 | I4: =JILL!M4 -> 59.73 | J4: =JILL!N4 -> 80.5 | K4: =J4*(1+K5) -> 96.6 | L4: =K4*(1+L5) -> 115.92 | M4: =L4*(1+M5) -> 127.512 | N4: =M4*(1+N5) -> 140.2632 | O4: =N4*(1+O5) -> 154.28952 | P4: =O4*(1+P5) -> 169.71847 | Q4: =P4*(1+Q5) -> 186.69032
B5: Growth % | C5: 0.2 | D5: 0.1 | F5: ='mgmt '!I25 -> 0.18757834 | G5: =G4/F4-1 -> 0.16797457 | H5: =H4/G4-1 -> 0.24723247 | I5: =I4/H4-1 -> 0.76715976 | J5: =J4/I4-1 -> 0.34773146 | K5: =C5 -> 0.2 | L5: =K5 -> 0.2 | M5: =D5 -> 0.1 | N5: =M5 -> 0.1 | O5: =N5 -> 0.1 | P5: =O5 -> 0.1 | Q5: =P5 -> 0.1
B7: COGS | C7: YoY Improvement | F7: ='mgmt '!I48 -> 9.4435091 | G7: ='Standalone Case'!G7 -> 10.942581 | H7: =JILL!L7 -> 13.6 | I7: =JILL!M7 -> 22.06 | J7: =JILL!N7 -> 31.1 | K7: =K4*K8 -> 37.32 | L7: =L4*L8 -> 44.784 | M7: =M4*M8 -> 49.2624 | N7: =N4*N8 -> 54.18864 | O7: =O4*O8 -> 59.607504 | P7: =P4*P8 -> 65.568254 | Q7: =Q4*Q8 -> 72.12508
B8: % Revenue | C8: 0 | D8: 0 | F8: =F7/F4 -> 0.40700289 | G8: =G7/G4 -> 0.40378528 | H8: =H7/H4 -> 0.40236686 | I8: =I7/I4 -> 0.36932865 | J8: =J7/J4 -> 0.3863354 | K8: =J8+$C8 -> 0.3863354 | L8: =K8+$C8 -> 0.3863354 | M8: =L8+$D8 -> 0.3863354 | N8: =M8+$D8 -> 0.3863354 | O8: =N8+$D8 -> 0.3863354 | P8: =O8+$D8 -> 0.3863354 | Q8: =P8+$D8 -> 0.3863354
B10: GROSS PROFIT | F10: =F4-F7 -> 13.759051 | G10: =G4-G7 -> 16.157419 | H10: =H4-H7 -> 20.2 | I10: =I4-I7 -> 37.67 | J10: =J4-J7 -> 49.4 | K10: =K4-K7 -> 59.28 | L10: =L4-L7 -> 71.136 | M10: =M4-M7 -> 78.2496 | ... Q10: =Q4-Q7 -> 114.56524
B11: % Margin | F11: =F10/F4 -> 0.59299711 | G11: =G10/G4 -> 0.59621472 | H11: =H10/H4 -> 0.59763314 | I11: =I10/I4 -> 0.63067135 | J11: =J10/J4 -> 0.6136646 | K11: =K10/K4 -> 0.6136646 | L11: =L10/L4 -> 0.6136646 | M11: =M10/M4 -> 0.6136646 | ... Q11: =Q10/Q4 -> 0.6136646
B13: OPEX: | J13: `
B14: S&M | F14: ='mgmt '!I65+'mgmt '!I64 -> 7.727007 | G14: ='Standalone Case'!G14 -> 7.614628 | H14: =JILL!L14 -> 9.9 | I14: =JILL!M14 -> 14.3 | J14: =JILL!N14 -> 16.4 | K14: =K$4*K21 -> 19.68 | L14: =L$4*L21 -> 23.616 | M14: =M$4*M21 -> 25.9776 | N14: =N$4*N21 -> 28.57536 | O14: =O$4*O21 -> 31.432896 | P14: =P$4*P21 -> 34.576186 | Q14: =Q$4*Q21 -> 38.033804
B15: R&D | F15: ='mgmt '!I63+'mgmt '!I66+'mgmt '!I67+'mgmt '!I69 -> 7.308554 | G15: ='Standalone Case'!G15 -> 6.992441 | H15: =JILL!L15 -> 1.7 | I15: =JILL!M15 -> 3.4 | J15: =JILL!N15 -> 0.4 | K15: =K$4*K22 -> 0.48 | L15: =L$4*L22 -> 0.576 | M15: =M$4*M22 -> 0.6336 | N15: =N$4*N22 -> 0.69696 | O15: =O$4*O22 -> 0.766656 | P15: =P$4*P22 -> 0.8433216 | Q15: =Q$4*Q22 -> 0.92765376
B16: G&A | F16: ='mgmt '!I70-('Synergy Base Case - old'!F14+'Synergy Base Case - old'!F15) -> 0.11225 | G16: ='Standalone Case'!G16 -> 0.018178 | H16: =JILL!L16 -> 11.3 | I16: =JILL!M16 -> 13.6 | J16: =JILL!N16 -> 15.1 | K16: =K$4*K23 -> 18.12 | L16: =L$4*L23 -> 21.744 | M16: =M$4*M23 -> 23.9184 | N16: =N$4*N23 -> 26.31024 | O16: =O$4*O23 -> 28.941264 | P16: =P$4*P23 -> 31.83539 | Q16: =Q$4*Q23 -> 35.018929
B17: OPEX | F17: =SUM(F14:F16) -> 15.147811 | G17: =SUM(G14:G16) -> 14.625247 | H17: =SUM(H14:H16) -> 22.9 | I17: =SUM(I14:I16) -> 31.3 | J17: =SUM(J14:J16) -> 31.9 | K17: =SUM(K14:K16) -> 38.28 | L17: =SUM(L14:L16) -> 45.936 | M17: =SUM(M14:M16) -> 50.5296 | ... Q17: =SUM(Q14:Q16) -> 73.980387
B18: % Revenue | F18: =F17/F4 -> 0.65285085 | G18: =G17/G4 -> 0.53967701 | H18: =H17/H4 -> 0.67751479 | I18: =I17/I4 -> 0.52402478 | J18: =J17/J4 -> 0.39627329 | K18: =K17/K4 -> 0.39627329 | L18: =L17/L4 -> 0.39627329 | M18: =M17/M4 -> 0.39627329 | ... Q18: =Q17/Q4 -> 0.39627329
B20: OPEX % Revenue: | C20: YoY Improvement
B21: S&M | C21: 0 | D21: 0 | F21: =F14/F$4 -> 0.3330239 | G21: =G14/G$4 -> 0.28098258 | H21: =H14/H$4 -> 0.29289941 | I21: =I14/I$4 -> 0.23941068 | J21: =J14/J$4 -> 0.20372671 | K21: =J21+$C21 -> 0.20372671 | L21: =K21+$C21 -> 0.20372671 | M21: =L21+$D21 -> 0.20372671 | N21: =M21+$D21 -> 0.20372671 | O21: =N21+$D21 -> 0.20372671 | P21: =O21+$D21 -> 0.20372671 | Q21: =P21+$D21 -> 0.20372671
B22: R&D | C22: 0 | D22: 0 | F22: =F15/F$4 -> 0.31498912 | G22: =G15/G$4 -> 0.25802365 | H22: =H15/H$4 -> 0.050295858 | I22: =I15/I$4 -> 0.056922819 | J22: =J15/J$4 -> 0.0049689441 | K22: =J22+$C22 -> 0.0049689441 | L22: =K22+$C22 -> 0.0049689441 | M22: =L22+$D22 -> 0.0049689441 | N22: =M22+$D22 -> 0.0049689441 | O22: =N22+$D22 -> 0.0049689441 | P22: =O22+$D22 -> 0.0049689441 | Q22: =P22+$D22 -> 0.0049689441
B23: G&A | C23: 0 | D23: 0 | F23: =F16/F$4 -> 0.0048378282 | G23: =G16/G$4 -> 0.00067077491 | H23: =H16/H$4 -> 0.33431953 | I23: =I16/I$4 -> 0.22769128 | J23: =J16/J$4 -> 0.18757764 | K23: =J23+$C23 -> 0.18757764 | L23: =K23+$C23 -> 0.18757764 | M23: =L23+$D23 -> 0.18757764 | N23: =M23+$D23 -> 0.18757764 | O23: =N23+$D23 -> 0.18757764 | P23: =O23+$D23 -> 0.18757764 | Q23: =P23+$D23 -> 0.18757764
B24: Total Opex % | G24: =SUM(G21:G23) -> 0.53967701 | H24: =SUM(H21:H23) -> 0.67751479 | I24: =SUM(I21:I23) -> 0.52402478 | J24: =SUM(J21:J23) -> 0.39627329
F25: =F10-F17 -> -1.3887601
B26: EBIT | F26: =F25/F4 -> -0.059853744 | G26: =G10-G17 -> 1.532172 | H26: =H10-H17 -> -2.7 | I26: =I10-I17 -> 6.37 | J26: =J10-J17 -> 17.5 | K26: =K10-K17 -> 21 | L26: =L10-L17 -> 25.2 | M26: =M10-M17 -> 27.72 | N26: =N10-N17 -> 30.492 | ... Q26: =Q10-Q17 -> 40.584852
B27: % Margin | G27: =G26/G4 -> 0.056537712 | H27: =H26/H4 -> -0.079881657 | I27: =I26/I4 -> 0.10664658 | J27: =J26/J4 -> 0.2173913 | K27: =K26/K4 -> 0.2173913 | L27: =L26/L4 -> 0.2173913 | M27: =M26/M4 -> 0.2173913 | N27: =N26/N4 -> 0.2173913 | ... Q27: =Q26/Q4 -> 0.2173913
B29: D&A | F29: ='mgmt '!I86 -> 0.99483639 | G29: ='Standalone Case'!G29 -> 2.2 | H29: =JILL!H29 -> 1.28 | I29: =JILL!I29 -> 1.3 | J29: =JILL!J29 -> 2.8 | K29: =K4*K30 -> 5.064 | L29: =L4*L30 -> 6.0768 | M29: =M4*M30 -> 6.68448 | N29: =N4*N30 -> 7.352928 | O29: =O4*O30 -> 8.0882208 | P29: =P4*P30 -> 8.8970429 | Q29: =Q4*Q30 -> 9.7867472
B30: % Revenue | C30: =C36 -> 0.05242236 | D30: =C30 -> 0.05242236 | F30: =F29/F4 -> 0.042876148 | G30: =G29/G4 -> 0.081180812 | H30: =H29/H4 -> 0.037869822 | I30: =I29/I4 -> 0.021764607 | J30: =J29/J4 -> 0.034782609 | K30: =C30 -> 0.05242236 | L30: =K30 -> 0.05242236 | M30: =D30 -> 0.05242236 | N30: =M30 -> 0.05242236 | O30: =N30 -> 0.05242236 | P30: =O30 -> 0.05242236 | Q30: =P30 -> 0.05242236
B32: EBITDA | F32: =F25+F29 -> -0.3939237 | G32: =G26+G29 -> 3.732172 | H32: =H26+H29 -> -1.42 | I32: =I26+I29 -> 7.67 | J32: =J26+J29 -> 20.3 | K32: =K26+K29 -> 26.064 | L32: =L26+L29 -> 31.2768 | M32: =M26+M29 -> 34.40448 | N32: =N26+N29 -> 37.844928 | ... Q32: =Q26+Q29 -> 50.371599
B33: % Margin | F33: =F32/F4 -> -0.016977596 | G33: =G32/G4 -> 0.13771852 | H33: =H32/H4 -> -0.042011834 | I33: =I32/I4 -> 0.12841118 | J33: =J32/J4 -> 0.25217391 | K33: =K32/K4 -> 0.26981366 | L33: =L32/L4 -> 0.26981366 | M33: =M32/M4 -> 0.26981366 | ... Q33: =Q32/Q4 -> 0.26981366
B35: Capex (HST) | F35: 0 | G35: =JILL!G35 -> 1 | H35: =JILL!L29 -> 1.34 | I35: =JILL!M29 -> 2.42 | J35: =JILL!N29 -> 4.22 | K35: =K4*K36 -> 5.064 | L35: =L4*L36 -> 6.0768 | M35: =M4*M36 -> 6.68448 | N35: =N4*N36 -> 7.352928 | O35: =O4*O36 -> 8.0882208 | P35: =P4*P36 -> 8.8970429 | Q35: =Q4*Q36 -> 9.7867472
B36: % Revenue | C36: =J36 -> 0.05242236 | D36: =C36 -> 0.05242236 | F36: =F35/F4 -> 0 | G36: =G35/G4 -> 0.036900369 | H36: =H35/H4 -> 0.03964497 | I36: =I35/I4 -> 0.040515654 | J36: =J35/J4 -> 0.05242236 | K36: =C36 -> 0.05242236 | L36: =K36 -> 0.05242236 | M36: =D36 -> 0.05242236 | N36: =M36 -> 0.05242236 | O36: =N36 -> 0.05242236 | P36: =O36 -> 0.05242236 | Q36: =P36 -> 0.05242236
A39: DCF
G40: PERIOD | H40: 1 | I40: 2 | J40: 3 | K40: 4 | L40: 5 | M40: =L40+1 -> 6 | N40: =M40+1 -> 7 | O40: =N40+1 -> 8 | P40: =O40+1 -> 9 | Q40: =P40+1 -> 10
B41: NWC | C41: 0.15 | G41: =G4*$C$41 -> 4.065 | H41: =H4*$C$41 -> 5.07 | I41: =I4*$C$41 -> 8.9595 | J41: =J4*$C$41 -> 12.075 | K41: =K4*$C$41 -> 14.49 | L41: =L4*$C$41 -> 17.388 | M41: =M4*$C$41 -> 19.1268 | N41: =N4*$C$41 -> 21.03948 | ... Q41: =Q4*$C$41 -> 28.003548
B42: Change in NWC | H42: =H41-G41 -> 1.005 | I42: =I41-H41 -> 3.8895 | J42: =J41-I41 -> 3.1155 | K42: =K41-J41 -> 2.415 | L42: =L41-K41 -> 2.898 | M42: =M41-L41 -> 1.7388 | N42: =N41-M41 -> 1.91268 | O42: =O41-N41 -> 2.103948 | ... Q42: =Q41-P41 -> 2.5457771
B44: EBIT | H44: =H26 -> -2.7 | I44: =I26 -> 6.37 | J44: =J26 -> 17.5 | K44: =K26 -> 21 | L44: =L26 -> 25.2 | M44: =M26 -> 27.72 | N44: =N26 -> 30.492 | O44: =O26 -> 33.5412 | ... Q44: =Q26 -> 40.584852
B45: - Taxes | C45: 0.2 | H45: =H44*$C$45 -> -0.54 | I45: =-I44*$C$45 -> -1.274 | J45: =-J44*$C$45 -> -3.5 | K45: =-K44*$C$45 -> -4.2 | L45: =-L44*$C$45 -> -5.04 | M45: =-M44*$C$45 -> -5.544 | N45: =-N44*$C$45 -> -6.0984 | O45: =-O44*$C$45 -> -6.70824 | P45: =-P44*$C$45 -> -7.379064 | Q45: =-Q44*$C$45 -> -8.1169704
B46: +NOL | C46: 1 | H46: =IF(-H45<=$C$46,-H45,($C$46)) -> 0.54 | I46: =IF(-I45<=$C$46,-I45,($C$46)) -> 1 | J46: =IF(-J45<=$C$46,-J45,($C$46)) -> 1 | K46: =IF(-K45<=$C$46,-K45,($C$46)) -> 1 | L46: =IF(-L45<=$C$46,-L45,($C$46)) -> 1 | M46: =IF(-M45<=$C$46,-M45,($C$46)) -> 1 | N46: =IF(-N45<=$C$46,-N45,($C$46)) -> 1 | O46: =IF(-O45<=$C$46,-O45,($C$46)) -> 1 | ... Q46: =IF(-Q45<=$C$46,-Q45,($C$46)) -> 1
B47: - Capex | H47: =-H35 -> -1.34 | I47: =-I35 -> -2.42 | J47: =-J35 -> -4.22 | K47: =-K35 -> -5.064 | L47: =-L35 -> -6.0768 | M47: =-M35 -> -6.68448 | N47: =-N35 -> -7.352928 | O47: =-O35 -> -8.0882208 | ... Q47: =-Q35 -> -9.7867472
B48: + D&A | H48: =H29 -> 1.28 | I48: =I29 -> 1.3 | J48: =J29 -> 2.8 | K48: =K29 -> 5.064 | L48: =L29 -> 6.0768 | M48: =M29 -> 6.68448 | N48: =N29 -> 7.352928 | O48: =O29 -> 8.0882208 | ... Q48: =Q29 -> 9.7867472
B49: +/- Changes in NWC | H49: =H42 -> 1.005 | I49: =I42 -> 3.8895 | J49: =J42 -> 3.1155 | K49: =K42 -> 2.415 | L49: =L42 -> 2.898 | M49: =M42 -> 1.7388 | N49: =N42 -> 1.91268 | O49: =O42 -> 2.103948 | ... Q49: =Q42 -> 2.5457771
B50: Free Cash Flow | H50: =SUM(H44:H49) -> -1.755 | I50: =SUM(I44:I49) -> 8.8655 | J50: =SUM(J44:J49) -> 16.6955 | K50: =SUM(K44:K49) -> 20.215 | L50: =SUM(L44:L49) -> 24.058 | M50: =SUM(M44:M49) -> 24.9148 | N50: =SUM(N44:N49) -> 27.30628 | O50: =SUM(O44:O49) -> 29.936908 | ... Q50: =SUM(Q44:Q49) -> 36.013659
B52: Period # | H52: 1 | I52: =H52+1 -> 2 | J52: =I52+1 -> 3 | K52: =J52+1 -> 4 | L52: =K52+1 -> 5 | M52: =L52+1 -> 6 | N52: =M52+1 -> 7 | O52: =N52+1 -> 8 | P52: =O52+1 -> 9 | Q52: =P52+1 -> 10 | R52: TV
...

Sheet DEAL COMPS
A2: DEAL COMPS
A4: ($ in millions)
I5: Purchsae | Q5: PP /
A6: Announced | C6: Acquirer | E6: Target | G6: Target Description | I6: Price (PP) | K6: LTM Revenue | M6: Gross Profit | O6: =U6 -> EBITDA | Q6: Revenue | S6: Gross Profit | U6: EBITDA
A8: April 2017 | C8: BioTelemetry | E8: LifeWatch | G8: Provider of remote cardiac monitoring diagnostic services for healthcare professionals. | I8: 239 | K8: 114 | M8: =K8*49% -> 55.86 | O8: =I8*5% -> 11.95 | Q8: =$I8/K8 -> 2.0964912 | S8: =$I8/M8 -> 4.2785535 | U8: =$I8/O8 -> 20
A9: Sept 2014 | C9: Preventice | E9: eCardio Diagnostics | G9: Provider of ambulatory cardiac monitoring products and services for arrhythmia diagnosis | I9: 150 | K9: 50 | M9: =I9*56% -> 84 | O9: =I9*14% -> 21 | Q9: =$I9/K9 -> 3 | S9: =$I9/M9 -> 1.7857143 | U9: =$I9/O9 -> 7.1428571
A10: Aug 2013 | C10: Medtronic | E10: Cardiocom | G10: Manufacturer and distributor of health monitoring products for multiple chronic diseases | I10: 200 | K10: 37 | M10: NA | O10: NA | Q10: =$I10/K10 -> 5.4054054 | S10: =M10 -> NA | U10: =O10 -> NA
A11: Aug 2012 | C11: Linde | E11: Lincare | G11: Supplier of durable / home medical equipment such as hospital beds, wheelchairs, CPAP, pulsox, etc. | I11: 3600 | K11: 1963.961 | M11: 1327.185 | O11: 470.071 | Q11: =$I11/K11 -> 1.8330303 | S11: =$I11/M11 -> 2.7125081 | U11: =$I11/O11 -> 7.6584176
I14: 75th Percentile | Q14: =PERCENTILE(Q8:Q11, 0.75) -> 3.6013514 | S14: =PERCENTILE(S8:S11, 0.75) -> 3.4955308 | U14: =PERCENTILE(U8:U11, 0.75) -> 13.829209
I15: Median | Q15: =MEDIAN(Q8:Q11) -> 2.5482456 | S15: =MEDIAN(S8:S11) -> 2.7125081 | U15: =MEDIAN(U8:U11) -> 7.6584176
I16: 25th Percentile | Q16: =PERCENTILE(Q8:Q11, 0.25) -> 2.030626 | S16: =PERCENTILE(S8:S11, 0.25) -> 2.2491112 | U16: =PERCENTILE(U8:U11, 0.25) -> 7.4006374
E19: Nola (2018A) | K19: ='Standalone Case'!G4 -> 27.1 | M19: =#REF! -> #REF! | O19: NM
A21: Sources: PitchBook, Company Financials, Piper Jaffery, Public Filings & Internal Company Estimates.
A26: Nov 2017 | C26: Altus Capital | E26: MGC Diagnostics | I26: 62.1 | K26: 40.464 | M26: 19.852 | O26: 0.593 | Q26: =$I26/K26 -> 1.5346975 | S26: =$I26/M26 -> 3.1281483 | U26: =$I26/O26 -> 104.72175

Sheet Pub Comps
C1: PUB COMPS
A3: 43531 | C3: ($ in millions)
G4: Share | K4: Revenue | O4: Revenue Growth % | S4: GM % | U4: EBITDA | Y4: EBITDA % | AD4: EV/Revenue | AH4: EV/EBITDA
A5: ID | B5: Category | E5: Company | G5: Price | I5: EV | K5: 2018A | L5: 2019E | M5: 2020E | O5: 2018A-2019E | Q5: 2019E-2020E | S5: 2018A | U5: 2018A | V5: 2019E | W5: 2020E | Y5: 2018A | Z5: 2019E | AA5: 2020E | AD5: 2018A | AF5: 2019E | AH5: =AD5 -> 2018A | AJ5: =AF5 -> 2019E
A6: =A51 | B6: Diagnostics | C6: DIAGNOSTICS | E6: BioTelemetry | G6: 67.19 | I6: 2358.3805 | K6: 389.373 | L6: 440.9 | M6: 485.8 | O6: =L6/K6-1 -> 0.13233326 | Q6: =M6/L6-1 -> 0.10183715 | S6: 0.63098746 | U6: 91.101 | V6: 127.864 | W6: 143.297 | Y6: =U6/K6 -> 0.23396846 | Z6: =V6/L6 -> 0.2900068 | AA6: =W6/M6 -> 0.29497118 | AD6: =$I6/K6 -> 6.0568671 | AF6: =$I6/L6 -> 5.3490145 | AH6: =$I6/U6 -> 25.887537 | AJ6: =$I6/V6 -> 18.444445
A7: =A49 | B7: Diagnostics | E7: Inogen | G7: 97.23 | I7: 1880.7132 | K7: 358.111 | L7: 435 | M7: 519.848 | O7: =L7/K7-1 -> 0.21470717 | Q7: =M7/L7-1 -> 0.19505287 | S7: 0.48604062 | U7: 48.491 | V7: 70.208 | W7: 85.4 | Y7: =U7/K7 -> 0.13540774 | Z7: =V7/L7 -> 0.1613977 | AA7: =W7/M7 -> 0.16427879 | AD7: =$I7/K7 -> 5.2517606 | AF7: =$I7/L7 -> 4.3234787 | AH7: =$I7/U7 -> 38.78479 | AJ7: =$I7/V7 -> 26.787734
A8: =A48 | B8: Diagnostics | E8: iRhythm | G8: 89.89 | I8: 2155.5855 | K8: 147.293 | L8: 205.4 | M8: 268.073 | O8: =L8/K8-1 -> 0.3944994 | Q8: =M8/L8-1 -> 0.30512658 | S8: 0.71872621 | U8: -42.852 | V8: -36.722 | W8: 12 | Y8: NM | Z8: NM | AA8: =W8/M8 -> 0.044763926 | AD8: =$I8/K8 -> 14.634677 | AF8: =$I8/M8 -> 8.0410392 | AH8: NM | AJ8: NM
A9: =A50 | B9: Sleep | C9: SLEEP | E9: Fisher & Paykel | G9: 10.188263 | I9: 5828.5847 | K9: 688.77114 | L9: 742.527 | M9: 822.245 | O9: =L9/K9-1 -> 0.078046043 | Q9: =M9/L9-1 -> 0.10736041 | S9: 0.65039919 | U9: 224.59152 | V9: 234.377 | W9: 277.335 | Y9: =U9/K9 -> 0.32607569 | Z9: =V9/L9 -> 0.31564778 | AA9: =W9/M9 -> 0.33728998 | AD9: =$I9/K9 -> 8.4622952 | AF9: =$I9/L9 -> 7.8496602 | AH9: =$I9/U9 -> 25.951935 | AJ9: =$I9/V9 -> 24.868416
A10: =A47 | B10: Sleep | E10: Itamar Medical | G10: 0.35788383 | I10: 106.79799 | K10: 20.701 | L10: NA | M10: NA | O10: NA | Q10: NA | S10: 0.72998915 | U10: -0.28 | V10: NA | W10: NA | Y10: NM | Z10: NA | AA10: NA | AD10: =$I10/K10 -> 5.1590738 | AF10: NM | AH10: NM | AJ10: NM
A11: =A46 | B11: Sleep | E11: ResMed | G11: 100.49 | I11: 15448.228 | K11: 2340.196 | L11: 2601 | M11: 2881 | O11: =L11/K11-1 -> 0.11144537 | Q11: =M11/L11-1 -> 0.1076509 | S11: 0.58146973 | U11: 653.249 | V11: 775.189 | W11: 860.071 | Y11: =U11/K11 -> 0.27914286 | Z11: =V11/L11 -> 0.29803499 | AA11: =W11/M11 -> 0.29853211 | AD11: =$I11/K11 -> 6.6012539 | AF11: =$I11/L11 -> 5.9393418 | AH11: =$I11/U11 -> 23.648299 | AJ11: =$I11/V11 -> 19.928337
V14: 75th Percentile | Y14: =PERCENTILE(Y6:Y11, 0.75) -> 0.29087607 | Z14: =PERCENTILE(Z6:Z11, 0.75) -> 0.30243819 | AA14: =PERCENTILE(AA6:AA11, 0.75) -> 0.29853211 | AD14: =PERCENTILE(AD6:AD11, 0.75) -> 7.9970348 | AF14: =PERCENTILE(AF6:AF11, 0.75) -> 7.8496602 | AH14: =PERCENTILE(AH6:AH11, 0.75) -> 29.160149 | AJ14: =PERCENTILE(AJ6:AJ11, 0.75) -> 25.348245
V15: Median | Y15: =MEDIAN(Y6:Y11) -> 0.25655566 | Z15: =MEDIAN(Z6:Z11) -> 0.2940209 | AA15: =MEDIAN(AA6:AA11) -> 0.29497118 | AD15: =MEDIAN(AD6:AD11) -> 6.3290605 | AF15: =MEDIAN(AF6:AF11) -> 5.9393418 | AH15: =MEDIAN(AH6:AH11) -> 25.919736 | AJ15: =MEDIAN(AJ6:AJ11) -> 22.398377
V16: 25th Percentile | Y16: =PERCENTILE(Y6:Y11, 0.25) -> 0.20932828 | Z16: =PERCENTILE(Z6:Z11, 0.25) -> 0.25785453 | AA16: =PERCENTILE(AA6:AA11, 0.25) -> 0.16427879 | AD16: =PERCENTILE(AD6:AD11, 0.25) -> 5.4530372 | AF16: =PERCENTILE(AF6:AF11, 0.25) -> 5.3490145 | AH16: =PERCENTILE(AH6:AH11, 0.25) -> 25.327728 | AJ16: =PERCENTILE(AJ6:AJ11, 0.25) -> 19.557364
E19: Standalone Case | K19: ='Standalone Case'!G4 -> 27.1 | L19: ='Standalone Case'!H4 -> 31.8 | M19: ='Standalone Case'!I4 -> 45.2 | O19: =L19/K19-1 -> 0.17343173 | Q19: =M19/L19-1 -> 0.42138365 | S19: ='Standalone Case'!G11 -> 0.59621472 | U19: ='Standalone Case'!G32 -> 3.732172 | V19: ='Standalone Case'!H32 -> 0.48 | W19: ='Standalone Case'!I32 -> 5.3 | Y19: =U19/K19 -> 0.13771852 | Z19: =V19/L19 -> 0.01509434 | AA19: =W19/M19 -> 0.11725664
E20: Synergy Base Case | K20: =K19 -> 27.1 | L20: ='SYNERGY CASE '!H4 -> 33.8 | M20: ='SYNERGY CASE '!I4 -> 59.73 | O20: =L20/K20-1 -> 0.24723247 | Q20: =M20/L20-1 -> 0.76715976 | S20: =S19 -> 0.59621472 | U20: =U19 -> 3.732172 | V20: ='SYNERGY CASE '!H32 -> -1.42 | W20: ='SYNERGY CASE '!I32 -> 7.67 | Y20: =U20/K20 -> 0.13771852 | Z20: =V20/L20 -> -0.042011834 | AA20: =W20/M20 -> 0.12841118
E22: Sources: PitchBook, Company Financials, Piper Jaffery, Public Filings & Internal Company Estimates. Enterprise Value calculation based off stock closing price of [March 9, 2019]

Sheet FOOTBALL FIELD
D1: THINKCELL | S1: IMPLIED DCF
H3: CHECK | K3: Discount Rate %
A4: DCF | C4: Standalone Case | D4: =U4 -> 65.244941 | E4: =T4-U4 -> 3.0647751 | F4: =S4-T4 -> 3.2884153 | H4: =SUM(D4:F4)-S4 -> 0 | K4: ='Standalone Case'!Z65 -> 0.175 | L4: ='Standalone Case'!AA65 -> 0.18 | M4: ='Standalone Case'!AB65 -> 0.185 | S4: ='Standalone Case'!Z68 -> 71.598132 | T4: ='Standalone Case'!AA68 -> 68.309717 | U4: ='Standalone Case'!AB68 -> 65.244941
A5: DCF | C5: Synergy Base Case | D5: =U5 -> 124.5825 | E5: =T5-U5 -> 5.5798016 | F5: =S5-T5 -> 5.9892907 | H5: =SUM(D5:F5)-S5 -> 0 | K5: =K4 -> 0.175 | L5: =L4 -> 0.18 | M5: =M4 -> 0.185 | S5: ='Synergy Base Case - old'!Z68 -> 136.1516 | T5: ='Synergy Base Case - old'!AA68 -> 130.16231 | U5: ='Synergy Base Case - old'!AB68 -> 124.5825
K7: 0.25 | L7: Median | M7: 0.75 | O7: Nola Revenue:
A8: Deal Comps | C8: =O8 -> 2018 (Actual) | D8: =S8 -> 55.029964 | E8: =T8-S8 -> 14.027492 | F8: =U8-T8 -> 28.539165 | H8: =SUM(D8:F8)-U8 -> 0 | K8: ='DEAL COMPS'!Q16 -> 2.030626 | L8: ='DEAL COMPS'!Q15 -> 2.5482456 | M8: ='DEAL COMPS'!Q14 -> 3.6013514 | O8: 2018 (Actual) | P8: =I27 -> 27.1 | S8: =$K$8*$P$8 -> 55.029964 | T8: =L$8*$P$8 -> 69.057456 | U8: =M$8*$P$8 -> 97.596622
K10: 0.25 | L10: Median | M10: 0.75 | O10: Nola Revenue by Case: | R10: Pub Discount
A11: Pub Comps | C11: 2018A Revenue | D11: =S11 -> 110.83298 | E11: =T11-S11 -> 60.684557 | F11: =U11-T11 -> 45.202105 | H11: =SUM(D11:F11)-U11 -> 0 | K11: ='Pub Comps'!AD16 -> 5.4530372 | L11: ='Pub Comps'!AD15 -> 6.3290605 | M11: ='Pub Comps'!AD14 -> 7.9970348 | O11: 2018 (Actual) | P11: =I27 -> 27.1 | R11: 0.25 | S11: =($K$11*$P$11)*(1-$R$11) -> 110.83298 | T11: =L$11*$P$11 -> 171.51754 | U11: =M$11*$P$11 -> 216.71964
A12: Pub Comps | C12: 2019E Standalone Case | D12: =S12 -> 170.09866 | E12: =T12-S12 -> 18.772406 | F12: =U12-T12 -> 60.748128 | H12: =SUM(D12:F12)-U12 -> 0 | K12: ='Pub Comps'!AF16 -> 5.3490145 | L12: ='Pub Comps'!AF15 -> 5.9393418 | M12: ='Pub Comps'!AF14 -> 7.8496602 | O12: 2019E (Standalone) | P12: =J27 -> 31.8 | S12: =K$12*$P$12 -> 170.09866 | T12: =L$12*$P$12 -> 188.87107 | U12: =M$12*$P$12 -> 249.6192
A13: Pub Comps | C13: 2019E Synergy Base Case | D13: =S13 -> 180.79669 | E13: =T13-S13 -> 19.95306 | F13: =U13-T13 -> 64.568764 | H13: =SUM(D13:F13)-U13 -> 0 | K13: =K12 -> 5.3490145 | L13: =L12 -> 5.9393418 | M13: =M12 -> 7.8496602 | O13: 2019E (Synergy Base) | P13: =J28 -> 33.8 | S13: =K$13*$P$13 -> 180.79669 | T13: =L$13*$P$13 -> 200.74975 | U13: =M$13*$P$13 -> 265.31852
A15: Pub Comps (25% discount) | C15: 2018A Revenue | D15: =S15 -> 83.124736 | E15: =T15-S15 -> 45.513418 | F15: =U15-T15 -> 33.901579 | S15: =S11*(1-R$11) -> 83.124736 | T15: =T11*(1-$R$11) -> 128.63815 | U15: =U11*(1-$R$11) -> 162.53973
A16: Pub Comps (25% discount) | C16: 2019E Standalone Case | D16: =S16 -> 127.574 | E16: =T16-S16 -> 14.079304 | F16: =U16-T16 -> 45.561096 | S16: =S12*(1-R$11) -> 127.574 | T16: =T12*(1-$R$11) -> 141.6533 | U16: =U12*(1-$R$11) -> 187.2144
A17: Pub Comps (25% discount) | C17: 2019E Synergy Base Case | D17: =S17 -> 135.59752 | E17: =T17-S17 -> 14.964795 | F17: =U17-T17 -> 48.426573 | S17: =S13*(1-R$11) -> 135.59752 | T17: =T13*(1-$R$11) -> 150.56231 | U17: =U13*(1-$R$11) -> 198.98889
K22: Notes: DCF analysis based on midpoint of 17.5 - 19.5% discount rate and 3.0% terminal value growth rate over ten-year horizon; M&A deal comps and public trading comparable multiple data sources include Pitchbook, Factset, Piper Jaffery and internal management estimates as of March 2019.
I25: Nola Base Revenue
C26: Nola Revenue: | I26: 2018A | J26: 2019E
C27: Standalone Case | I27: ='Standalone Case'!G4 -> 27.1 | J27: ='Standalone Case'!H4 -> 31.8
C28: Synergy Case | I28: =I27 -> 27.1 | J28: ='Synergy Base Case - old'!H4 -> 33.8
M36: ]

Sheet bio - Cash Flow
M2: 2012 | N2: 2013 | O2: 2014 | P2: 2015 | Q2: 2016 | R2: 2017 | S2: 2018 | T2: 2011 | U2: 2010 | V2: 2009 | W2: 2008 | X2: 2007 | Y2: 2006 | Z2: 2005 | AA2: 2004
C3: Cash Flow (Fiscal Year)
C4: Downloaded On: 10-Mar-2019 | D4: Summary Stats
C5: Company: BioTelemetry (NAS: BEAT) | D5: Median | E5: Mean | F5: Min | G5: Max | H5: 25th pctile | I5: 75th pctile | J5: Std. Dev | K5: Coefficient of Variation | M5: FY 2012 | N5: FY 2013 | O5: FY 2014 | P5: FY 2015 | Q5: FY 2016 | R5: FY 2017 | S5: FY 2018 | T5: FY 2011 | U5: FY 2010 | V5: FY 2009 | W5: FY 2008 | X5: FY 2007 | Y5: FY 2006 | Z5: FY 2005 | AA5: FY 2004 | AB5: FY 2003
C6: Amounts in Thousands, USD (except Ratios, Multiples & per share items)
O8: Filed: 22-Feb-2017 | S8: Filed: 22-Feb-2019 | U8: Filed: 31-Dec-2010 | V8: Filed: 31-Dec-2009 | W8: Filed: 31-Dec-2008 | X8: Filed: 31-Dec-2007
O9: View 10-K | S9: View 10-K | U9: View 10-K | V9: View 10-K | W9: View 10-K | X9: View 10-K
A10: 1 | C10: Cash Flow from Operating Activities, Indirect
A11: 1 | C11: Net Cash Flow from Continuing Operating Activities, Indirect
A12: 1 | C12: Cash Generated from Operating Activities
A13: 1 | C13: Income/(Loss) before Non-Cash Adjustment | D13: -7644.732 | E13: -3405.6717 | F13: -61422 | G13: 53437 | H13: -17143 | I13: 7428 | J13: 28628.701 | K13: -8.4061835 | M13: -12202 | N13: -7319 | O13: -9793 | P13: 7428 | Q13: 53437 | R13: -17143 | S13: 41874 | T13: -61422 | U13: -19860 | V13: -20476 | W13: 9205 | X13: -358 | Y13: -7644.732
A14: 1 | C14: Adjustments for Non-Cash Items
A15: 1 | C15: Depreciation, Amortization and Depletion, Non-Cash Adjustment | D15: 12132 | E15: 13905.407 | F15: 2656.291 | G15: 40168 | H15: 9378 | I15: 12550 | J15: 9950.2155 | K15: 0.71556449 | M15: 9378 | N15: 12318 | O15: 12550 | P15: 12488 | Q15: 14269 | R15: 28561 | S15: 40168 | T15: 12132 | U15: 12071 | V15: 10937 | W15: 8693 | X15: 4549 | Y15: 2656.291
