Workbook

Sheet Executive AI Model
A1: AI Startup Executive Cost Model
A2: Simple front sheet for CFO and technical executives. Edit blue-font inputs only. Green-font cells are formula-driven.
A4: 1. Core Inputs | D4: Executive Snapshot | H4: Hidden model logic keeps the interface lean: 1. Revenue grows monthly in Year 1 from the starting ARR. 2. Net hires ramp evenly through the first 12 months. 3. Years 2-10 revenue growth fades linearly to terminal growth. 4. Post-Year-1 headcount scales at 40% of revenue growth. 5. Cash taxes apply only when operating profit is positive.
A5: Starting cash ($) | B5: 7500000 | D5: Year 1 Revenue | F5: =Q24
A6: Starting ARR ($) | B6: 6000000 | D6: Year 1 Cash Burn | F6: =Q35
A7: Year 1 ARR growth | B7: 0.6 | D7: Year 1 Operating Profit | F7: =Q31
A8: Gross margin | B8: 0.72 | D8: Ending Cash After 12 Months | F8: =O35
A9: Starting headcount | B9: 28 | D9: DCF Enterprise Value | F9: =IF($B$14<=$B$17,"n/a",SUM(Q38:Z38)+((Z34*(1+$B$17))/($B$14-$B$17))*Z37)
A10: Planned net new hires in next 12 months | B10: 12 | D10: Year 10 Revenue | F10: =Z24
A11: Annual fully loaded cost per FTE ($) | B11: 210000
A12: AI infra + tooling as % of revenue | B12: 0.14
A13: Other operating costs as % of revenue | B13: 0.18
A14: Discount rate | B14: 0.18
A16: 2. Built-in Defaults
A17: Terminal growth | B17: 0.03
A18: Cash tax rate | B18: 0.25
A19: Capex as % of revenue | B19: 0.03
A20: Headcount growth factor vs. revenue growth | B20: 0.4
A21: Annual payroll inflation | B21: 0.03
A22: 3. Monthly Cash Burn: Next 12 Months | Q22: 4. Annual View: Years 1-10
D23: =$B$22 | E23: =EDATE($B$22,1) | F23: =EDATE($B$22,2) | G23: =EDATE($B$22,3) | H23: =EDATE($B$22,4) | I23: =EDATE($B$22,5) | J23: =EDATE($B$22,6) | K23: =EDATE($B$22,7) | L23: =EDATE($B$22,8) | M23: =EDATE($B$22,9) | N23: =EDATE($B$22,10) | O23: =EDATE($B$22,11) | Q23: Year 1 | R23: Year 2 | S23: Year 3 | T23: Year 4 | U23: Year 5 | V23: Year 6 | W23: Year 7 | X23: Year 8 | Y23: Year 9 | Z23: Year 10
A24: Revenue | D24: =$B$6/12 | E24: =D24*(1+(1+$B$7)^(1/12)-1) | F24: =E24*(1+(1+$B$7)^(1/12)-1) | G24: =F24*(1+(1+$B$7)^(1/12)-1) | H24: =G24*(1+(1+$B$7)^(1/12)-1) | I24: =H24*(1+(1+$B$7)^(1/12)-1) | J24: =I24*(1+(1+$B$7)^(1/12)-1) | K24: =J24*(1+(1+$B$7)^(1/12)-1) | L24: =K24*(1+(1+$B$7)^(1/12)-1) | ... O24: =N24*(1+(1+$B$7)^(1/12)-1) | P24: Revenue | Q24: =SUM(D24:O24) | R24: =Q24*(1+R25) | S24: =R24*(1+S25) | T24: =S24*(1+T25) | U24: =T24*(1+U25) | V24: =U24*(1+V25) | W24: =V24*(1+W25) | X24: =W24*(1+X25) | Y24: =X24*(1+Y25) | Z24: =Y24*(1+Z25)
A25: Gross Profit | D25: =D24*$B$8 | E25: =E24*$B$8 | F25: =F24*$B$8 | G25: =G24*$B$8 | H25: =H24*$B$8 | I25: =I24*$B$8 | J25: =J24*$B$8 | K25: =K24*$B$8 | ... O25: =O24*$B$8 | P25: Revenue Growth | Q25: =$B$7 | R25: =$B$7+(($B$17-$B$7)*1/9) | S25: =$B$7+(($B$17-$B$7)*2/9) | T25: =$B$7+(($B$17-$B$7)*3/9) | U25: =$B$7+(($B$17-$B$7)*4/9) | V25: =$B$7+(($B$17-$B$7)*5/9) | W25: =$B$7+(($B$17-$B$7)*6/9) | X25: =$B$7+(($B$17-$B$7)*7/9) | Y25: =$B$7+(($B$17-$B$7)*8/9) | Z25: =$B$7+(($B$17-$B$7)*9/9)
A26: Ending Headcount | D26: =$B$9+(1*$B$10/12) | E26: =$B$9+(2*$B$10/12) | F26: =$B$9+(3*$B$10/12) | G26: =$B$9+(4*$B$10/12) | H26: =$B$9+(5*$B$10/12) | I26: =$B$9+(6*$B$10/12) | J26: =$B$9+(7*$B$10/12) | K26: =$B$9+(8*$B$10/12) | L26: =$B$9+(9*$B$10/12) | M26: =$B$9+(10*$B$10/12) | N26: =$B$9+(11*$B$10/12) | O26: =$B$9+(12*$B$10/12) | P26: Gross Profit | Q26: =Q24*$B$8 | R26: =R24*$B$8 | S26: =S24*$B$8 | T26: =T24*$B$8 | U26: =U24*$B$8 | V26: =V24*$B$8 | W26: =W24*$B$8 | X26: =X24*$B$8 | ... Z26: =Z24*$B$8
A27: Payroll | D27: =D26*$B$11/12 | E27: =E26*$B$11/12 | F27: =F26*$B$11/12 | G27: =G26*$B$11/12 | H27: =H26*$B$11/12 | I27: =I26*$B$11/12 | J27: =J26*$B$11/12 | K27: =K26*$B$11/12 | ... O27: =O26*$B$11/12 | P27: Ending Headcount | Q27: =O26 | R27: =Q27*(1+MAX(R25*$B$20,0)) | S27: =R27*(1+MAX(S25*$B$20,0)) | T27: =S27*(1+MAX(T25*$B$20,0)) | U27: =T27*(1+MAX(U25*$B$20,0)) | V27: =U27*(1+MAX(V25*$B$20,0)) | W27: =V27*(1+MAX(W25*$B$20,0)) | X27: =W27*(1+MAX(X25*$B$20,0)) | Y27: =X27*(1+MAX(Y25*$B$20,0)) | Z27: =Y27*(1+MAX(Z25*$B$20,0))
A28: AI Infra + Tooling | D28: =D24*$B$12 | E28: =E24*$B$12 | F28: =F24*$B$12 | G28: =G24*$B$12 | H28: =H24*$B$12 | I28: =I24*$B$12 | J28: =J24*$B$12 | K28: =K24*$B$12 | ... O28: =O24*$B$12 | P28: Payroll | Q28: =SUM(D27:O27) | R28: =R27*$B$11*(1+$B$21)^1 | S28: =S27*$B$11*(1+$B$21)^2 | T28: =T27*$B$11*(1+$B$21)^3 | U28: =U27*$B$11*(1+$B$21)^4 | V28: =V27*$B$11*(1+$B$21)^5 | W28: =W27*$B$11*(1+$B$21)^6 | X28: =X27*$B$11*(1+$B$21)^7 | Y28: =Y27*$B$11*(1+$B$21)^8 | Z28: =Z27*$B$11*(1+$B$21)^9
A29: Other Operating Costs | D29: =D24*$B$13 | E29: =E24*$B$13 | F29: =F24*$B$13 | G29: =G24*$B$13 | H29: =H24*$B$13 | I29: =I24*$B$13 | J29: =J24*$B$13 | K29: =K24*$B$13 | ... O29: =O24*$B$13 | P29: AI Infra + Tooling | Q29: =Q24*$B$12 | R29: =R24*$B$12 | S29: =S24*$B$12 | T29: =T24*$B$12 | U29: =U24*$B$12 | V29: =V24*$B$12 | W29: =W24*$B$12 | X29: =X24*$B$12 | ... Z29: =Z24*$B$12
A30: Operating Profit | D30: =D25-D27-D28-D29 | E30: =E25-E27-E28-E29 | F30: =F25-F27-F28-F29 | G30: =G25-G27-G28-G29 | H30: =H25-H27-H28-H29 | I30: =I25-I27-I28-I29 | J30: =J25-J27-J28-J29 | K30: =K25-K27-K28-K29 | ... O30: =O25-O27-O28-O29 | P30: Other Operating Costs | Q30: =Q24*$B$13 | R30: =R24*$B$13 | S30: =S24*$B$13 | T30: =T24*$B$13 | U30: =U24*$B$13 | V30: =V24*$B$13 | W30: =W24*$B$13 | X30: =X24*$B$13 | ... Z30: =Z24*$B$13
A31: Cash Taxes | D31: =MAX(D30,0)*$B$18 | E31: =MAX(E30,0)*$B$18 | F31: =MAX(F30,0)*$B$18 | G31: =MAX(G30,0)*$B$18 | H31: =MAX(H30,0)*$B$18 | I31: =MAX(I30,0)*$B$18 | J31: =MAX(J30,0)*$B$18 | K31: =MAX(K30,0)*$B$18 | ... O31: =MAX(O30,0)*$B$18 | P31: Operating Profit | Q31: =Q26-Q28-Q29-Q30 | R31: =R26-R28-R29-R30 | S31: =S26-S28-S29-S30 | T31: =T26-T28-T29-T30 | U31: =U26-U28-U29-U30 | V31: =V26-V28-V29-V30 | W31: =W26-W28-W29-W30 | X31: =X26-X28-X29-X30 | ... Z31: =Z26-Z28-Z29-Z30
A32: Capex | D32: =D24*$B$19 | E32: =E24*$B$19 | F32: =F24*$B$19 | G32: =G24*$B$19 | H32: =H24*$B$19 | I32: =I24*$B$19 | J32: =J24*$B$19 | K32: =K24*$B$19 | ... O32: =O24*$B$19 | P32: Cash Taxes | Q32: =MAX(Q31,0)*$B$18 | R32: =MAX(R31,0)*$B$18 | S32: =MAX(S31,0)*$B$18 | T32: =MAX(T31,0)*$B$18 | U32: =MAX(U31,0)*$B$18 | V32: =MAX(V31,0)*$B$18 | W32: =MAX(W31,0)*$B$18 | X32: =MAX(X31,0)*$B$18 | ... Z32: =MAX(Z31,0)*$B$18
A33: Free Cash Flow | D33: =D30-D31-D32 | E33: =E30-E31-E32 | F33: =F30-F31-F32 | G33: =G30-G31-G32 | H33: =H30-H31-H32 | I33: =I30-I31-I32 | J33: =J30-J31-J32 | K33: =K30-K31-K32 | ... O33: =O30-O31-O32 | P33: Capex | Q33: =Q24*$B$19 | R33: =R24*$B$19 | S33: =S24*$B$19 | T33: =T24*$B$19 | U33: =U24*$B$19 | V33: =V24*$B$19 | W33: =W24*$B$19 | X33: =X24*$B$19 | ... Z33: =Z24*$B$19
A34: Cash Burn | D34: =MAX(-D33,0) | E34: =MAX(-E33,0) | F34: =MAX(-F33,0) | G34: =MAX(-G33,0) | H34: =MAX(-H33,0) | I34: =MAX(-I33,0) | J34: =MAX(-J33,0) | K34: =MAX(-K33,0) | ... O34: =MAX(-O33,0) | P34: Free Cash Flow | Q34: =Q31-Q32-Q33 | R34: =R31-R32-R33 | S34: =S31-S32-S33 | T34: =T31-T32-T33 | U34: =U31-U32-U33 | V34: =V31-V32-V33 | W34: =W31-W32-W33 | X34: =X31-X32-X33 | ... Z34: =Z31-Z32-Z33
A35: Ending Cash | D35: =$B$5+D33 | E35: =D35+E33 | F35: =E35+F33 | G35: =F35+G33 | H35: =G35+H33 | I35: =H35+I33 | J35: =I35+J33 | K35: =J35+K33 | L35: =K35+L33 | ... O35: =N35+O33 | P35: Cash Burn | Q35: =MAX(-Q34,0) | R35: =MAX(-R34,0) | S35: =MAX(-S34,0) | T35: =MAX(-T34,0) | U35: =MAX(-U34,0) | V35: =MAX(-V34,0) | W35: =MAX(-W34,0) | X35: =MAX(-X34,0) | ... Z35: =MAX(-Z34,0)
P36: Ending Cash | Q36: =O35 | R36: =Q36+R34 | S36: =R36+S34 | T36: =S36+T34 | U36: =T36+U34 | V36: =U36+V34 | W36: =V36+W34 | X36: =W36+X34 | Y36: =X36+Y34 | Z36: =Y36+Z34
P37: Discount Factor | Q37: =1/(1+$B$14)^1 | R37: =1/(1+$B$14)^2 | S37: =1/(1+$B$14)^3 | T37: =1/(1+$B$14)^4 | U37: =1/(1+$B$14)^5 | V37: =1/(1+$B$14)^6 | W37: =1/(1+$B$14)^7 | X37: =1/(1+$B$14)^8 | Y37: =1/(1+$B$14)^9 | Z37: =1/(1+$B$14)^10
A38: 5. Visuals | P38: PV of Free Cash Flow | Q38: =Q34*Q37 | R38: =R34*R37 | S38: =S34*S37 | T38: =T34*T37 | U38: =U34*U37 | V38: =V34*V37 | W38: =W34*W37 | X38: =X34*X37 | ... Z38: =Z34*Z37
A55: Interpretation guide: Cash burn is shown as a positive number only when free cash flow is negative. Operating profit is shown before financing. DCF is based on Years 1-10 free cash flow plus a terminal value using the built-in terminal growth assumption.

Sheet Ats Slide
A1: DELTA COST CENTRE MODEL - DRAFT&CONFIDENTIAL | Y1: STATUS | AI1: 1000000
B2: - Expect cash usage of $3m-$3.5m upon signing | Y2: Will Audrey be on the call later? | Z2: CHANGE TO MILLIONS
B3: - Delta is expected to add approx $3.8m to opex run - rate ($2.8m of which are headcount costs)
B4: - Includes 14 existing heads and 14 new hires (13 engineers plus 1 product designer)
B5: - cost centre will roll into Jon Oakes
B6: - 1-time integration/deal costs of $900k, additional costs of $452k expected to be negotiated as part of purchase price/working capital negotiation
B7: - Founder earnout of $2.25 is not included in the p&l
E9: 2019E | H9: 2020E | M9: 2021 | R9: 2022 | W9: TOTAL COSTS
C10: Provided by | E10: Q319 | F10: Q419 | G10: 2H19 | H10: 1Q20 | I10: 2Q20 | J10: 3Q20 | K10: 4Q20 | L10: FY2020 | M10: Q1 | N10: Q2 | O10: Q3 | P10: Q4 | Q10: FY | R10: Q1 | S10: Q2 | T10: Q3 | U10: Q4 | V10: FY | W10: FY 2019 - 2022
B11: Headcount (HC):
B12: Delta Employees | F12: =[1]Sheet1!$A$28 | G12: =F12 | H12: =G12 | I12: =H12 | J12: =I12 | K12: =J12 | L12: =K12 | M12: =L12 | N12: =M12 | ... W12: =V12
B13: New Asia Hires | F13: 6 | G13: =F13 | H13: 12 | I13: 12 | J13: 14 | K13: 14 | L13: =K13 | M13: 14 | N13: 14 | O13: 14 | P13: 14 | Q13: =P13 | R13: =P13 | S13: =R13 | T13: =S13 | U13: =T13 | V13: =U13 | W13: =V13 | Y13: 1.5m founder holdback, 25%, 25% and 50% - 375k in q4 2020 - new category
B14: Total Ending HC | F14: =F12+F13 | G14: =G12+G13 | H14: =H12+H13 | I14: =I12+I13 | J14: =J12+J13 | K14: =K12+K13 | L14: =L12+L13 | M14: =M12+M13 | ... V14: =V12+V13 | W14: =V14
B16: Run Rate Costs:
B17: =B12 | F17: =F43 | G17: =G43 | H17: =H43 | I17: =I43 | J17: =J43 | K17: =K43 | L17: =L43 | M17: =M43 | ... W17: =W43
B18: =B13 | F18: =F69 | G18: =G69 | H18: =H69 | I18: =I69 | J18: =J69 | K18: =K69 | L18: =L69 | M18: =M69 | ... W18: =W69 | Z18: More engineers | AA18: =(L18-L17)/L17
B19: Total HC Costs | F19: =F43+F69 | G19: =G43+G69 | H19: =H43+H69 | I19: =I43+I69 | J19: =J43+J69 | K19: =K43+K69 | L19: =L43+L69 | M19: =M43+M69 | ... W19: =W43+W69 | Z19: =L17+L18
B20: T&E | F20: =F85 | G20: =G85 | H20: =H85 | I20: =I85 | J20: =J85 | K20: =K85 | L20: =L85 | M20: =#REF!+M3 | N20: =#REF!+N3 | O20: =#REF!+O3 | P20: =#REF!+P3 | Q20: =SUM(M20:P20) | R20: =#REF!+R3 | S20: =#REF!+S3 | T20: =#REF!+T3 | U20: =#REF!+U3 | V20: =SUM(R20:U20) | W20: =G20+L20+Q20+V20
B21: Facility and Office Exp | F21: =F86 | G21: =G86 | H21: =H86 | I21: =I86 | J21: =J86 | K21: =K86 | L21: =L86 | M21: =#REF!+M4 | N21: =#REF!+N4 | O21: =#REF!+O4 | P21: =#REF!+P4 | Q21: =SUM(M21:P21) | R21: =#REF!+R4 | S21: =#REF!+S4 | T21: =#REF!+T4 | U21: =#REF!+U4 | V21: =SUM(R21:U21) | W21: =G21+L21+Q21+V21
B22: IT Costs - wi fi&special software | C22: Bill Bragg | F22: =F90 | G22: =G90 | H22: =H90 | I22: =I90 | J22: =J90 | K22: =K90 | L22: =L90 | M22: =K22 | N22: =M22 | O22: =N22 | P22: =M22 | Q22: =SUM(M22:P22) | R22: =M22 | S22: =R22 | T22: =S22 | U22: =S22 | V22: =SUM(R22:U22) | W22: =G22+L22+Q22+V22
B23: Engineering non h/c | C23: Paul Quinn | F23: =F93 | G23: =G93 | H23: =H93 | I23: =I93 | J23: =J93 | K23: =K93 | L23: =L93 | M23: =#REF! | N23: =#REF! | O23: =#REF! | P23: =#REF! | Q23: =SUM(M23:P23) | R23: =#REF! | S23: =#REF! | T23: =#REF! | U23: =#REF! | V23: =SUM(R23:U23) | W23: =#REF!
B24: Tax | C24: Anu/Harvey | F24: =F95 | G24: =G95 | H24: =H95 | I24: =I95 | J24: =J95 | K24: =K95 | L24: =L95 | M24: =#REF! | N24: =#REF! | O24: =#REF! | P24: =#REF! | Q24: =SUM(M24:P24) | R24: =#REF! | S24: =#REF! | T24: =#REF! | U24: =#REF! | V24: =SUM(R24:U24) | W24: =#REF! | Y24: Stamp duty cost - 2% of shares of company - would it go to p&l?
B25: Other | C25: Nish/Tom | F25: =F96 | G25: =G96 | H25: =H96 | I25: =I96 | J25: =J96 | K25: =K96 | L25: =L96 | M25: =#REF! | N25: =#REF! | O25: =#REF! | P25: =#REF! | Q25: =SUM(M25:P25) | R25: =#REF! | S25: =#REF! | T25: =#REF! | U25: =#REF! | V25: =SUM(R25:U25) | W25: =#REF!
B26: Non-HC Costs | F26: =F98-F19-F112 | G26: =G98-G19-G112 | H26: =H98-H19-H112 | I26: =I98-I19-I112 | J26: =J98-J19-J112 | K26: 231390.5 | L26: =SUM(H26:K26) | M26: =M98-M19-M112 | N26: =N98-N19-N112 | O26: =O98-O19-O112 | P26: =P98-P19-P112 | Q26: =Q98-Q19-Q112 | R26: =R98-R19-R112 | S26: =S98-S19-S112 | T26: =T98-T19-T112 | ... W26: =W98-W19-W112 | Z26: =SUM(H26:K26)
B27: Total Run Rate Costs | F27: =F19+F26 | G27: =G19+G26 | H27: =H19+H26 | I27: =I19+I26 | J27: =J19+J26 | K27: =K19+K26 | L27: =L19+L26 | M27: =M19+M26 | ... W27: =W19+W26
B29: Cost of goods sold
B30: Inventory write off - DokiPal units that we will not sell | C30: Audrey | F30: =100000 | G30: =SUM(E30:F30) | W30: =G30+L30+Q30+V30
B31: Inventory write off - Buy back of DokiPal units | F31: ='Recoverable units'!F20 | G31: =SUM(E31:F31) | W31: =G31+L31+Q31+V31
B33: Operating costs:
B35: Gross wages - yoy inc | H35: 0 | M35: 0.05 | R35: =M35
B36: Gross Wages | C36: HR | F36: =[1]Sheet1!$G$30/4 | G36: =SUM(E36:F36) | H36: =F36*(1+H35) | I36: =H36 | J36: =I36 | K36: =J36 | L36: =SUM(H36:K36) | M36: =H36*(1+M35) | N36: =M36 | O36: =N36 | P36: =O36 | Q36: =SUM(M36:P36) | R36: =M36*(1+R35) | S36: =R36 | T36: =S36 | U36: =T36 | V36: =SUM(R36:U36) | W36: =G36+L36+Q36+V36
B37: Bonus - yoy inc | H37: 0 | M37: 0.05 | R37: =M37 | W37: =G37+L37+Q37+V37
B38: Bonus | C38: HR | F38: =[1]Sheet1!$K$32/4 | G38: =SUM(E38:F38) | H38: =F38*(1+H37) | I38: =H38 | J38: =I38 | K38: =J38 | L38: =SUM(H38:K38) | M38: =H38*(1+M37) | N38: =M38 | O38: =N38 | P38: =O38 | Q38: =SUM(M38:P38) | R38: =M38*(1+R37) | S38: =R38 | T38: =S38 | U38: =T38 | V38: =SUM(R38:U38) | W38: =G38+L38+Q38+V38
B39: Fringe assumption | F39: 0.15 | G39: =F39 | H39: =G39 | I39: =H39 | J39: =I39 | K39: =J39 | L39: =K39 | M39: =L39 | N39: =M39 | ... V39: =U39 | W39: =G39+L39+Q39+V39
B40: Fringe | C40: HR | F40: =SUM(F36:F38)*$F$39 | G40: =SUM(E40:F40) | H40: =SUM(H36:H38)*$F$39 | I40: =SUM(I36:I38)*$F$39 | J40: =SUM(J36:J38)*$F$39 | K40: =SUM(K36:K38)*$F$39 | L40: =SUM(H40:K40) | M40: =SUM(M36:M38)*$F$39 | N40: =M40 | O40: =N40 | P40: =O40 | Q40: =SUM(M40:P40) | R40: =SUM(R36:R38)*$F$39 | S40: =SUM(S36:S38)*$F$39 | T40: =SUM(T36:T38)*$F$39 | U40: =SUM(U36:U38)*$F$39 | V40: =SUM(R40:U40) | W40: =G40+L40+Q40+V40
B41: Retention | C41: HR | F41: =((85000/18)*3)+(85000/36)*3 | G41: =SUM(E41:F41) | H41: =F41 | I41: =H41 | J41: =I41 | K41: =J41 | L41: =SUM(H41:K41) | M41: =K41 | N41: =(85000/36)*3 | O41: =N41 | P41: =O41 | Q41: =SUM(M41:P41) | R41: =N41 | S41: =R41 | T41: =S41 | V41: =SUM(R41:U41) | W41: =G41+L41+Q41+V41
B42: Severance | C42: HR | F42: 0 | G42: =SUM(E42:F42) | H42: 0 | I42: 0 | J42: 0 | K42: 0 | L42: =SUM(H42:K42) | M42: 0 | N42: =M42 | O42: =N42 | P42: =O42 | Q42: =SUM(M42:P42) | R42: 0 | S42: 0 | T42: 0 | U42: 0 | V42: =SUM(R42:U42) | W42: =G42+L42+Q42+V42
B43: HC Related costs | C43: HR | F43: =SUM(F36:F42) | G43: =SUM(E43:F43) | H43: =SUM(H36:H42) | I43: =SUM(I36:I42) | J43: =SUM(J36:J42) | K43: =SUM(K36:K42) | L43: =SUM(L36:L42) | M43: =SUM(M36:M42) | N43: =SUM(N36:N42) | O43: =SUM(O36:O42) | ... V43: =SUM(V36:V42) | W43: =G43+L43+Q43+V43 | AI43: HC Costs Copy of Delta Comp v2- 9.27.19 - Sent to Casper.xlsx
B44: T&E - per person p.a | F44: =5000/4 | G44: =SUM(E44:F44) | H44: =F44 | I44: =H44 | J44: =I44 | K44: =J44 | L44: =SUM(H44:K44) | M44: =H44 | N44: =I44 | O44: =J44 | P44: =K44 | Q44: =SUM(M44:P44) | R44: =M44 | S44: =N44 | T44: =O44 | U44: =P44 | V44: =SUM(R44:U44) | W44: =G44+L44+Q44+V44
B45: T&E | C45: FP&A | F45: =F12*$F44 | G45: =SUM(E45:F45) | H45: =H12*$F44 | I45: =I12*$F44 | J45: =J12*$F44 | K45: =K12*$F44 | L45: =SUM(H45:K45) | M45: =M12*$F44 | N45: =N12*$F44 | O45: =O12*$F44 | P45: =P12*$F44 | Q45: =SUM(M45:P45) | R45: =R12*$F44 | S45: =S12*$F44 | T45: =T12*$F44 | U45: =U12*$F44 | V45: =SUM(R45:U45) | W45: =G45+L45+Q45+V45
...

Sheet Financial model
A1: DELTA COST CENTRE MODEL - DRAFT&CONFIDENTIAL | Y1: STATUS
B2: - Expect cash usage of $3m-$3.5m upon signing | Y2: Will Audrey be on the call later?
B3: - Delta is expected to add approx $3.8m to opex run - rate ($2.8m of which are headcount costs)
B4: - Includes 14 existing heads and 14 new hires (13 engineers plus 1 product designer)
B5: - cost centre will roll into Jon Oakes
B6: - 1-time integration/deal costs of $900k, additional costs of $452k expected to be negotiated as part of purchase price/working capital negotiation
B7: - Founder earnout of $2.25 is not included in the p&l
E9: 2019 | H9: 2020 | M9: 2021 | R9: 2022 | W9: TOTAL COSTS
C10: Provided by | E10: Q3 | F10: Q4 | G10: FY | H10: Q1 | I10: Q2 | J10: Q3 | K10: Q4 | L10: FY | M10: Q1 | N10: Q2 | O10: Q3 | P10: Q4 | Q10: FY | R10: Q1 | S10: Q2 | T10: Q3 | U10: Q4 | V10: FY | W10: FY 2019 - 2022
B11: Delta Employees | F11: =[1]Sheet1!$A$28 | G11: =F11 | H11: =G11 | I11: =H11 | J11: =I11 | K11: =J11 | L11: =K11 | M11: =L11 | N11: =M11 | ... W11: =V11
B12: New Employees in HK | F12: 6 | G12: =F12 | H12: 12 | I12: 12 | J12: 14 | K12: 14 | L12: =K12 | M12: 14 | N12: 14 | O12: 14 | P12: 14 | Q12: =P12 | R12: =P12 | S12: =R12 | T12: =S12 | U12: =T12 | V12: =U12 | W12: =V12
B13: TOTAL DELTA HC | F13: =F11+F12 | G13: =G11+G12 | H13: =H11+H12 | I13: =I11+I12 | J13: =J11+J12 | K13: =K11+K12 | L13: =L11+L12 | M13: =M11+M12 | ... V13: =V11+V12 | W13: =V13
B15: Cost of goods sold
B16: Inventory write off - DokiPal units that we will not sell | C16: Audrey | F16: =100000 | G16: =SUM(E16:F16) | W16: =G16+L16+Q16+V16
B17: Inventory write off - Buy back of DokiPal units | F17: ='Recoverable units'!F20 | G17: =SUM(E17:F17) | W17: =G17+L17+Q17+V17
B19: Operating costs:
B21: Gross wages - yoy inc | H21: 0 | M21: 0.05 | R21: =M21
B22: Gross Wages | C22: HR | F22: =[1]Sheet1!$G$30/4 | G22: =SUM(E22:F22) | H22: =F22*(1+H21) | I22: =H22 | J22: =I22 | K22: =J22 | L22: =SUM(H22:K22) | M22: =H22*(1+M21) | N22: =M22 | O22: =N22 | P22: =O22 | Q22: =SUM(M22:P22) | R22: =M22*(1+R21) | S22: =R22 | T22: =S22 | U22: =T22 | V22: =SUM(R22:U22) | W22: =G22+L22+Q22+V22
B23: Bonus - yoy inc | H23: 0 | M23: 0.05 | R23: =M23 | W23: =G23+L23+Q23+V23
B24: Bonus | C24: HR | F24: =[1]Sheet1!$K$32/4 | G24: =SUM(E24:F24) | H24: =F24*(1+H23) | I24: =H24 | J24: =I24 | K24: =J24 | L24: =SUM(H24:K24) | M24: =H24*(1+M23) | N24: =M24 | O24: =N24 | P24: =O24 | Q24: =SUM(M24:P24) | R24: =M24*(1+R23) | S24: =R24 | T24: =S24 | U24: =T24 | V24: =SUM(R24:U24) | W24: =G24+L24+Q24+V24
B25: Fringe assumption | F25: 0.15 | G25: =F25 | H25: =G25 | I25: =H25 | J25: =I25 | K25: =J25 | L25: =K25 | M25: =L25 | N25: =M25 | ... V25: =U25 | W25: =G25+L25+Q25+V25
B26: Fringe | C26: HR | F26: =SUM(F22:F24)*$F$25 | G26: =SUM(E26:F26) | H26: =SUM(H22:H24)*$F$25 | I26: =SUM(I22:I24)*$F$25 | J26: =SUM(J22:J24)*$F$25 | K26: =SUM(K22:K24)*$F$25 | L26: =SUM(H26:K26) | M26: =SUM(M22:M24)*$F$25 | N26: =M26 | O26: =N26 | P26: =O26 | Q26: =SUM(M26:P26) | R26: =SUM(R22:R24)*$F$25 | S26: =SUM(S22:S24)*$F$25 | T26: =SUM(T22:T24)*$F$25 | U26: =SUM(U22:U24)*$F$25 | V26: =SUM(R26:U26) | W26: =G26+L26+Q26+V26
B27: Retention | C27: HR | F27: =((85000/18)*3)+(85000/36)*3 | G27: =SUM(E27:F27) | H27: =F27 | I27: =H27 | J27: =I27 | K27: =J27 | L27: =SUM(H27:K27) | M27: =K27 | N27: =(85000/36)*3 | O27: =N27 | P27: =O27 | Q27: =SUM(M27:P27) | R27: =N27 | S27: =R27 | T27: =S27 | V27: =SUM(R27:U27) | W27: =G27+L27+Q27+V27
B28: Severance | C28: HR | F28: 0 | G28: =SUM(E28:F28) | H28: 0 | I28: 0 | J28: 0 | K28: 0 | L28: =SUM(H28:K28) | M28: 0 | N28: =M28 | O28: =N28 | P28: =O28 | Q28: =SUM(M28:P28) | R28: 0 | S28: 0 | T28: 0 | U28: 0 | V28: =SUM(R28:U28) | W28: =G28+L28+Q28+V28
B29: HC Related costs | C29: HR | F29: =SUM(F22:F28) | G29: =SUM(E29:F29) | H29: =SUM(H22:H28) | I29: =SUM(I22:I28) | J29: =SUM(J22:J28) | K29: =SUM(K22:K28) | L29: =SUM(L22:L28) | M29: =SUM(M22:M28) | N29: =SUM(N22:N28) | O29: =SUM(O22:O28) | ... V29: =SUM(V22:V28) | W29: =G29+L29+Q29+V29 | AI29: HC Costs Copy of Delta Comp v2- 9.27.19 - Sent to Casper.xlsx
B30: T&E - per person p.a | F30: =5000/4 | G30: =SUM(E30:F30) | H30: =F30 | I30: =H30 | J30: =I30 | K30: =J30 | L30: =SUM(H30:K30) | M30: =H30 | N30: =I30 | O30: =J30 | P30: =K30 | Q30: =SUM(M30:P30) | R30: =M30 | S30: =N30 | T30: =O30 | U30: =P30 | V30: =SUM(R30:U30) | W30: =G30+L30+Q30+V30
B31: T&E | C31: FP&A | F31: =F11*$F30 | G31: =SUM(E31:F31) | H31: =H11*$F30 | I31: =I11*$F30 | J31: =J11*$F30 | K31: =K11*$F30 | L31: =SUM(H31:K31) | M31: =M11*$F30 | N31: =N11*$F30 | O31: =O11*$F30 | P31: =P11*$F30 | Q31: =SUM(M31:P31) | R31: =R11*$F30 | S31: =S11*$F30 | T31: =T11*$F30 | U31: =U11*$F30 | V31: =SUM(R31:U31) | W31: =G31+L31+Q31+V31
B32: Facility and Office Exp | C32: Peter | F32: ='8) Facilities'!I41 | G32: =SUM(E32:F32) | H32: ='8) Facilities'!J41/H13*H11 | I32: ='8) Facilities'!K41/I13*I11 | J32: ='8) Facilities'!L41/J13*J11 | K32: ='8) Facilities'!M41/K13*K11 | L32: =SUM(H32:K32) | M32: =K32 | N32: =M32 | O32: =M32 | P32: =N32 | Q32: =SUM(M32:P32) | R32: =P32 | S32: =R32 | T32: =R32 | U32: =S32 | V32: =SUM(R32:U32) | W32: =G32+L32+Q32+V32
B33: IT Costs - security Blackduck | C33: Jonathan W | E33: ='13) IT- Security'!$H$41 | G33: =SUM(E33:F33) | L33: =SUM(H33:K33) | M33: =J33 | N33: =M33 | O33: =N33 | P33: =M33 | Q33: =SUM(M33:P33) | R33: =M33 | S33: =R33 | T33: =S33 | U33: =S33 | V33: =SUM(R33:U33) | W33: =G33+L33+Q33+V33
B34: IT Costs - laptops etc | C34: Bill Bragg | F34: ='11) IT-Infrastructure'!$I$41-F35 | G34: =SUM(E34:F34) | L34: =SUM(H34:K34) | M34: =J34 | N34: =M34 | O34: =N34 | P34: =M34 | Q34: =SUM(M34:P34) | R34: =M34 | S34: =R34 | T34: =S34 | U34: =S34 | V34: =SUM(R34:U34) | W34: =G34+L34+Q34+V34
B35: IT Costs - wi fi&special software | C35: Bill Bragg | F35: ='11) IT-Infrastructure'!$I$31+'11) IT-Infrastructure'!I34 | G35: =SUM(E35:F35) | H35: ='11) IT-Infrastructure'!$I$31+'11) IT-Infrastructure'!K34 | I35: ='11) IT-Infrastructure'!$I$31+'11) IT-Infrastructure'!L34 | J35: ='11) IT-Infrastructure'!$I$31+'11) IT-Infrastructure'!M34 | K35: ='11) IT-Infrastructure'!$I$31+'11) IT-Infrastructure'!N34 | L35: =SUM(H35:K35) | M35: =K35 | N35: =M35 | O35: =N35 | P35: =M35 | Q35: =SUM(M35:P35) | R35: =M35 | S35: =R35 | T35: =S35 | U35: =S35 | V35: =SUM(R35:U35) | W35: =G35+L35+Q35+V35
B36: Valuation reviews - BVA+External cost | C36: Heather | F36: =15000+30000 | G36: =SUM(E36:F36) | L36: =SUM(H36:K36) | Q36: =SUM(M36:P36) | V36: =SUM(R36:U36) | W36: =G36+L36+Q36+V36
B37: Legal expenses - external counsel | C37: Nisha | F37: 425000 | G37: =SUM(E37:F37) | L37: =SUM(H37:K37) | Q37: =SUM(M37:P37) | V37: =SUM(R37:U37) | W37: =G37+L37+Q37+V37
B38: Engineering - Agora + other aps | C38: Paul Quinn | F38: ='2) SW Eng'!$I$41 | G38: =SUM(E38:F38) | H38: ='2) SW Eng'!J41 | I38: ='2) SW Eng'!K41 | J38: ='2) SW Eng'!L41 | K38: ='2) SW Eng'!M41 | L38: =SUM(H38:K38) | M38: ='2) SW Eng'!N41 | N38: ='2) SW Eng'!O41 | O38: ='2) SW Eng'!P41 | P38: ='2) SW Eng'!Q41 | Q38: =SUM(M38:P38) | R38: ='2) SW Eng'!P41 | S38: ='2) SW Eng'!Q41 | T38: ='2) SW Eng'!R41 | U38: ='2) SW Eng'!S41 | V38: =SUM(R38:U38) | W38: =G38+L38+Q38+V38
B39: Operations | C39: Bobinder | E39: ='14) Operations'!$H$41 | F39: =E39 | G39: =SUM(E39:F39) | H39: =E39 | I39: =H39 | L39: =SUM(H39:K39) | Q39: =SUM(M39:P39) | V39: =SUM(R39:U39) | W39: =G39+L39+Q39+V39
B40: Tax - compliance costs | C40: Anu/Harvey | G40: =SUM(E40:F40) | I40: 12000 | L40: =SUM(H40:K40) | N40: =I40 | Q40: =SUM(M40:P40) | S40: =I40 | V40: =SUM(R40:U40) | W40: =G40+L40+Q40+V40
B41: Tax - stamp duty | C41: Legal | F41: =7500000*50%*0.2% | G41: =SUM(E41:F41) | L41: =SUM(H41:K41) | N41: =I41 | Q41: =SUM(M41:P41) | S41: =I41 | V41: =SUM(R41:U41) | W41: =G41+L41+Q41+V41
B42: Other | F42: 25000 | G42: =SUM(E42:F42) | H42: =F42 | I42: =G42 | J42: =H42 | K42: =I42 | L42: =SUM(H42:K42) | M42: =H42 | N42: =I42 | O42: =J42 | P42: =K42 | Q42: =SUM(M42:P42) | R42: =M42 | S42: =N42 | T42: =O42 | U42: =P42 | V42: =SUM(R42:U42) | W42: =G42+L42+Q42+V42
B43: Total Operating costs | F43: =F29+F31+SUM(F32:F42) | G43: =G29+G31+SUM(G32:G42) | H43: =H29+H31+SUM(H32:H42) | I43: =I29+I31+SUM(I32:I42) | J43: =J29+J31+SUM(J32:J42) | K43: =K29+K31+SUM(K32:K42) | L43: =L29+L31+SUM(L32:L42) | M43: =M29+M31+SUM(M32:M42) | ... V43: =V29+V31+SUM(V32:V42) | W43: =G43+L43+Q43+V43
B44: Total Costs associated with current employees | E44: =E22+E24+E26+E27+E28+E31+E32+E35+E36+E40+E38+E37+E42+E34+E39+E33+E16+E17 | F44: =F22+F24+F26+F27+F28+F31+F32+F35+F36+F40+F38+F37+F42+F34+F39+F33+F16+F17 | G44: =G22+G24+G26+G27+G28+G31+G32+G35+G36+G40+G38+G37+G42+G34+G39+G33+G16+G17 | H44: =H22+H24+H26+H27+H28+H31+H32+H35+H36+H40+H38+H37+H42+H34+H39+H33+H16+H17 | I44: =I22+I24+I26+I27+I28+I31+I32+I35+I36+I40+I38+I37+I42+I34+I39+I33+I16+I17 | J44: =J22+J24+J26+J27+J28+J31+J32+J35+J36+J40+J38+J37+J42+J34+J39+J33+J16+J17 | K44: =K22+K24+K26+K27+K28+K31+K32+K35+K36+K40+K38+K37+K42+K34+K39+K33+K16+K17 | L44: =L22+L24+L26+L27+L28+L31+L32+L35+L36+L40+L38+L37+L42+L34+L39+L33+L16+L17 | ... W44: =W22+W24+W26+W27+W28+W31+W32+W35+W36+W40+W38+W37+W42+W34+W39+W33+W16+W17
...

Sheet Recoverable units
A3: DokiPal Units as of September 1, 2019
B5: # in inventory at Doki | C5: # w/ channel Partners | D5: # sold into Market | E5: Sub-total Units | F5: # activated | G5: # active (last 30 days) | H5: # active (last 6 Months) (i.e., pinged server at least once in last 6 months) | I5: Warranty Period Length | J5: # units defective / warranty claim | K5: Cost of Replacements | L5: # Still Under warranty
B6: 3018 | C6: ? | D6: 4982 | E6: 8000 | F6: 2221 | G6: 2221 | H6: 2221 | I6: 12 months | J6: 55 | K6: $65/ unit | L6: All
C8: We don't have visibility on the # of units our distributors/ retailers have in stock | D8: This is the total # of units we sold through wholesale and online channels
E12: =D6-F6
B14: Added by LB:
B15: Invoice price disti would have paid | E15: =180*60% | M15: Q for Audrey - why multiply by 40% for returns?
A16: 0.1 | B16: 10% mark up to incentivise partners to return stock | E16: =E15*(1+A16)
B18: % of units able to repurchase | E18: 0.4 | F18: 0.5 | G18: 0.6 | H18: 0.7 | I18: 0.8 | J18: 0.9 | K18: 1 | M18: This is a q for Bobinder?
E20: =($E$12*E18)*$E$16 | F20: =($E$12*F18)*$E$16 | G20: =($E$12*G18)*$E$16 | H20: =($E$12*H18)*$E$16 | I20: =($E$12*I18)*$E$16 | J20: =($E$12*J18)*$E$16 | K20: =($E$12*K18)*$E$16 | M20: Will we write these off/keep them for returns/warranty (in which case a double hit to the p&l is showing)?

Sheet Stamp duty
B2: We wanted also to get back to the group on the stamp duty. The current rate of stamp duty is an aggregate of 0.2 percent (0.1 percent payable by each of Seller and Buyer) of the higher of (i) the purchase price or (ii) the value of the stock, which is typically the net asset value of the target as shown in its latest audited accounts. The determination of the purchase price (assuming it exceeds NAV) would (1) take into account any purchase price adjustments e.g. working capital adjustment and (2) include the maximum amount of the earnout. Fyi, there is an opportunity to apply for a refund of excessive stamp duty paid if turns out the actual earnout is less than the maximum, but the period to do so is limited to 2 years.

Sheet 2) SW Eng
A1: Delta Incremental Costs
A3: Headcount | H3: 2019 | J3: 2020 | N3: 2021 | R3: 2022
H4: 43647 | I4: 43739 | J4: 43831 | K4: 43922 | L4: 44013 | M4: 44105 | N4: 44197 | O4: 44287 | P4: 44378 | Q4: 44470 | R4: 44562 | S4: 44652
A5: Submitted by | B5: Department | C5: TBH Title | D5: Description | E5: Hire Date | F5: Location | G5: Base Salary Estimate USD | H5: Q3 | I5: Q4 | J5: Q1 | K5: Q2 | L5: Q3 | M5: Q4 | N5: Q1 | O5: Q2 | P5: Q3 | Q5: Q4 | R5: Q1 | S5: Q2
H6: =IF($E6<I$4,($G6*1.3)/4,0) | I6: =IF($E6<J$4,($G6*1.3)/4,0) | J6: =IF($E6<K$4,($G6*1.3)/4,0) | K6: =IF($E6<L$4,($G6*1.3)/4,0) | L6: =IF($E6<M$4,($G6*1.3)/4,0) | M6: =IF($E6<N$4,($G6*1.3)/4,0) | N6: =IF($E6<O$4,($G6*1.3)/4,0) | O6: =IF($E6<P$4,($G6*1.3)/4,0) | ... R6: =IF($E6<S$4,($G6*1.3)/4,0) | S6: =IF($E6<S$4,($G6*1.3)/4,0)
H7: =IF($E7<I$4,($G7*1.3)/4,0) | I7: =IF($E7<J$4,($G7*1.3)/4,0) | J7: =IF($E7<K$4,($G7*1.3)/4,0) | K7: =IF($E7<L$4,($G7*1.3)/4,0) | L7: =IF($E7<M$4,($G7*1.3)/4,0) | M7: =IF($E7<N$4,($G7*1.3)/4,0) | N7: =IF($E7<O$4,($G7*1.3)/4,0) | O7: =IF($E7<P$4,($G7*1.3)/4,0) | ... R7: =IF($E7<S$4,($G7*1.3)/4,0) | S7: =IF($E7<S$4,($G7*1.3)/4,0)
H8: =IF($E8<I$4,($G8*1.3)/4,0) | I8: =IF($E8<J$4,($G8*1.3)/4,0) | J8: =IF($E8<K$4,($G8*1.3)/4,0) | K8: =IF($E8<L$4,($G8*1.3)/4,0) | L8: =IF($E8<M$4,($G8*1.3)/4,0) | M8: =IF($E8<N$4,($G8*1.3)/4,0) | N8: =IF($E8<O$4,($G8*1.3)/4,0) | O8: =IF($E8<P$4,($G8*1.3)/4,0) | ... R8: =IF($E8<S$4,($G8*1.3)/4,0) | S8: =IF($E8<S$4,($G8*1.3)/4,0)
H9: =IF($E9<I$4,($G9*1.3)/4,0) | I9: =IF($E9<J$4,($G9*1.3)/4,0) | J9: =IF($E9<K$4,($G9*1.3)/4,0) | K9: =IF($E9<L$4,($G9*1.3)/4,0) | L9: =IF($E9<M$4,($G9*1.3)/4,0) | M9: =IF($E9<N$4,($G9*1.3)/4,0) | N9: =IF($E9<O$4,($G9*1.3)/4,0) | O9: =IF($E9<P$4,($G9*1.3)/4,0) | ... R9: =IF($E9<S$4,($G9*1.3)/4,0) | S9: =IF($E9<S$4,($G9*1.3)/4,0)
H10: =IF($E10<I$4,($G10*1.3)/4,0) | I10: =IF($E10<J$4,($G10*1.3)/4,0) | J10: =IF($E10<K$4,($G10*1.3)/4,0) | K10: =IF($E10<L$4,($G10*1.3)/4,0) | L10: =IF($E10<M$4,($G10*1.3)/4,0) | M10: =IF($E10<N$4,($G10*1.3)/4,0) | N10: =IF($E10<O$4,($G10*1.3)/4,0) | O10: =IF($E10<P$4,($G10*1.3)/4,0) | ... R10: =IF($E10<S$4,($G10*1.3)/4,0) | S10: =IF($E10<S$4,($G10*1.3)/4,0)
H11: =IF($E11<I$4,($G11*1.3)/4,0) | I11: =IF($E11<J$4,($G11*1.3)/4,0) | J11: =IF($E11<K$4,($G11*1.3)/4,0) | K11: =IF($E11<L$4,($G11*1.3)/4,0) | L11: =IF($E11<M$4,($G11*1.3)/4,0) | M11: =IF($E11<N$4,($G11*1.3)/4,0) | N11: =IF($E11<O$4,($G11*1.3)/4,0) | O11: =IF($E11<P$4,($G11*1.3)/4,0) | ... R11: =IF($E11<S$4,($G11*1.3)/4,0) | S11: =IF($E11<S$4,($G11*1.3)/4,0)
H12: =IF($E12<I$4,($G12*1.3)/4,0) | I12: =IF($E12<J$4,($G12*1.3)/4,0) | J12: =IF($E12<K$4,($G12*1.3)/4,0) | K12: =IF($E12<L$4,($G12*1.3)/4,0) | L12: =IF($E12<M$4,($G12*1.3)/4,0) | M12: =IF($E12<N$4,($G12*1.3)/4,0) | N12: =IF($E12<O$4,($G12*1.3)/4,0) | O12: =IF($E12<P$4,($G12*1.3)/4,0) | ... R12: =IF($E12<S$4,($G12*1.3)/4,0) | S12: =IF($E12<S$4,($G12*1.3)/4,0)
H13: =IF($E13<I$4,($G13*1.3)/4,0) | I13: =IF($E13<J$4,($G13*1.3)/4,0) | J13: =IF($E13<K$4,($G13*1.3)/4,0) | K13: =IF($E13<L$4,($G13*1.3)/4,0) | L13: =IF($E13<M$4,($G13*1.3)/4,0) | M13: =IF($E13<N$4,($G13*1.3)/4,0) | N13: =IF($E13<O$4,($G13*1.3)/4,0) | O13: =IF($E13<P$4,($G13*1.3)/4,0) | ... R13: =IF($E13<S$4,($G13*1.3)/4,0) | S13: =IF($E13<S$4,($G13*1.3)/4,0)
H14: =IF($E14<I$4,($G14*1.3)/4,0) | I14: =IF($E14<J$4,($G14*1.3)/4,0) | J14: =IF($E14<K$4,($G14*1.3)/4,0) | K14: =IF($E14<L$4,($G14*1.3)/4,0) | L14: =IF($E14<M$4,($G14*1.3)/4,0) | M14: =IF($E14<N$4,($G14*1.3)/4,0) | N14: =IF($E14<O$4,($G14*1.3)/4,0) | O14: =IF($E14<P$4,($G14*1.3)/4,0) | ... R14: =IF($E14<S$4,($G14*1.3)/4,0) | S14: =IF($E14<S$4,($G14*1.3)/4,0)
H15: =IF($E15<I$4,($G15*1.3)/4,0) | I15: =IF($E15<J$4,($G15*1.3)/4,0) | J15: =IF($E15<K$4,($G15*1.3)/4,0) | K15: =IF($E15<L$4,($G15*1.3)/4,0) | L15: =IF($E15<M$4,($G15*1.3)/4,0) | M15: =IF($E15<N$4,($G15*1.3)/4,0) | N15: =IF($E15<O$4,($G15*1.3)/4,0) | O15: =IF($E15<P$4,($G15*1.3)/4,0) | ... R15: =IF($E15<S$4,($G15*1.3)/4,0) | S15: =IF($E15<S$4,($G15*1.3)/4,0)
H16: =IF($E16<I$4,($G16*1.3)/4,0) | I16: =IF($E16<J$4,($G16*1.3)/4,0) | J16: =IF($E16<K$4,($G16*1.3)/4,0) | K16: =IF($E16<L$4,($G16*1.3)/4,0) | L16: =IF($E16<M$4,($G16*1.3)/4,0) | M16: =IF($E16<N$4,($G16*1.3)/4,0) | N16: =IF($E16<O$4,($G16*1.3)/4,0) | O16: =IF($E16<P$4,($G16*1.3)/4,0) | ... R16: =IF($E16<S$4,($G16*1.3)/4,0) | S16: =IF($E16<S$4,($G16*1.3)/4,0)
H17: =IF($E17<I$4,($G17*1.3)/4,0) | I17: =IF($E17<J$4,($G17*1.3)/4,0) | J17: =IF($E17<K$4,($G17*1.3)/4,0) | K17: =IF($E17<L$4,($G17*1.3)/4,0) | L17: =IF($E17<M$4,($G17*1.3)/4,0) | M17: =IF($E17<N$4,($G17*1.3)/4,0) | N17: =IF($E17<O$4,($G17*1.3)/4,0) | O17: =IF($E17<P$4,($G17*1.3)/4,0) | ... R17: =IF($E17<S$4,($G17*1.3)/4,0) | S17: =IF($E17<S$4,($G17*1.3)/4,0)
... H24: =IF($E24<I$4,($G24*1.3)/4,0) | I24: =IF($E24<J$4,($G24*1.3)/4,0) | J24: =IF($E24<K$4,($G24*1.3)/4,0) | K24: =IF($E24<L$4,($G24*1.3)/4,0) | L24: =IF($E24<M$4,($G24*1.3)/4,0) | M24: =IF($E24<N$4,($G24*1.3)/4,0) | N24: =IF($E24<O$4,($G24*1.3)/4,0) | O24: =IF($E24<P$4,($G24*1.3)/4,0) | ... R24: =IF($E24<S$4,($G24*1.3)/4,0) | S24: =IF($E24<S$4,($G24*1.3)/4,0)
H25: =SUM(H6:H24) | I25: =SUM(I6:I24) | J25: =SUM(J6:J24) | K25: =SUM(K6:K24) | L25: =SUM(L6:L24) | M25: =SUM(M6:M24) | N25: =SUM(N6:N24) | O25: =SUM(O6:O24) | ... S25: =SUM(S6:S24)
A27: Non Headcount | H27: 2019 | J27: 2020 | N27: 2021 | R27: 2022
A28: Submitted by | B28: Department | C28: Description of Spend | D28: Justification | G28: Total Cost Estimate | H28: Q3 | I28: Q4 | J28: Q1 | K28: Q2 | L28: Q3 | M28: Q4 | N28: Q1 | O28: Q2 | P28: Q3 | Q28: Q4 | R28: Q1 | S28: Q2
A29: LB (Based on email from Paul Quinn) | B29: Agora | C29: Set up a new Fitbit owned Agora account - 10k to 50k | D29: Shares video calling API use with another company. This may incur unforeseen costs as we support their existing in-market devices for a yea | I29: =50000/4 | J29: =I29 | K29: =J29 | L29: =K29
A31: Engineering | B31: licensing for devt tools - current employees | C31: Licensing for development tools | G31: $500 per engineering employee per year listed above (new hire) - for above people in Hong Kong office | I31: ='I. TECH'!J26*(500/4) | J31: ='I. TECH'!K26*(500/4) | K31: ='I. TECH'!L26*(500/4) | L31: ='I. TECH'!M26*(500/4) | M31: ='I. TECH'!N26*(500/4) | N31: ='I. TECH'!O26*(500/4) | O31: ='I. TECH'!P26*(500/4) | P31: ='I. TECH'!Q26*(500/4) | ... S31: ='I. TECH'!T26*(500/4)
B32: licensing for devt tools - new employees | G32: $500 per engineering employee per year listed above (existing ) - for above people in Hong Kong office | I32: =14*(500/4) | J32: =14*(500/4) | K32: =14*(500/4) | L32: =14*(500/4) | M32: =14*(500/4) | N32: =14*(500/4) | O32: =14*(500/4) | P32: =14*(500/4) | ... S32: =14*(500/4)
A33: Ryan Krems | B33: Product | C33: Recruiting Budget | D33: Need to get new-hires on-board - 2 months of average salary per new hire
A35: adde by LB based on email from Ryan | B35: For 4Q2019 only as we will want to support the PRC mode for a limited time only. | D35: alibaba cloud | I35: 1000
A36: adde by LB based on email from Ryan | B36: Github - Yes - Through 4Q2020 (small amount, want to make sure it isn't effecting their work flow for existing users) | I36: =344/8*3 | J36: =I36 | K36: =J36 | L36: =K36 | M36: =L36
A37: adde by LB based on email from Ryan | B37: Mailchimp - Yes - Through 4Q2020 (would expect this to be a much smaller amount that they were having before) | I37: =1600/8*3 | J37: =I37 | K37: =J37 | L37: =K37 | M37: =L37
A38: adde by LB based on email from Ryan | B38: Linode - Yes - Through 4Q2020 (not sure what they are using for, but a really small amount) | I38: =80/8*3 | J38: =I38 | K38: =J38 | L38: =K38 | M38: =L38
A39: adde by LB based on email from Ryan | B39: AWS - Yes - Through 4Q2020 (this is to support their current user base) | I39: =7081/8*3 | J39: =I39 | K39: =J39 | L39: =K39 | M39: =L39
A40: adde by LB based on email from Ryan | B40: Google Cloud - Yes - Through 4Q2019 (expect these to all be rolled over to Fitbit infra by EOY) | I40: =16400/8*3
G41: =SUM(G29:G40) | H41: =SUM(H29:H34) | I41: =SUM(I29:I40) | J41: =SUM(J29:J40) | K41: =SUM(K29:K40) | L41: =SUM(L29:L40) | M41: =SUM(M29:M40) | N41: =SUM(N29:N40) | O41: =SUM(O29:O40) | P41: =SUM(P29:P40) | ... S41: =SUM(S29:S40)

Sheet 4) Accounting
A1: Delta Incremental Costs
A3: Headcount | H3: 2019 | J3: 2020 | N3: 2021 | R3: 2022
H4: 43647 | I4: 43739 | J4: 43831 | K4: 43922 | L4: 44013 | M4: 44105 | N4: 44197 | O4: 44287 | P4: 44378 | Q4: 44470 | R4: 44562 | S4: 44652
A5: Submitted by | B5: Department | C5: TBH Title | D5: Description | E5: Hire Date | F5: Location | G5: Base Salary Estimate USD | H5: Q3 | I5: Q4 | J5: Q1 | K5: Q2 | L5: Q3 | M5: Q4 | N5: Q1 | O5: Q2 | P5: Q3 | Q5: Q4 | R5: Q1 | S5: Q2
H6: =IF($E6<I$4,($G6*1.3)/4,0) | I6: =IF($E6<J$4,($G6*1.3)/4,0) | J6: =IF($E6<K$4,($G6*1.3)/4,0) | K6: =IF($E6<L$4,($G6*1.3)/4,0) | L6: =IF($E6<M$4,($G6*1.3)/4,0) | M6: =IF($E6<N$4,($G6*1.3)/4,0) | N6: =IF($E6<O$4,($G6*1.3)/4,0) | O6: =IF($E6<P$4,($G6*1.3)/4,0) | ... R6: =IF($E6<S$4,($G6*1.3)/4,0) | S6: =IF($E6<S$4,($G6*1.3)/4,0)
H7: =IF($E7<I$4,($G7*1.3)/4,0) | I7: =IF($E7<J$4,($G7*1.3)/4,0) | J7: =IF($E7<K$4,($G7*1.3)/4,0) | K7: =IF($E7<L$4,($G7*1.3)/4,0) | L7: =IF($E7<M$4,($G7*1.3)/4,0) | M7: =IF($E7<N$4,($G7*1.3)/4,0) | N7: =IF($E7<O$4,($G7*1.3)/4,0) | O7: =IF($E7<P$4,($G7*1.3)/4,0) | ... R7: =IF($E7<S$4,($G7*1.3)/4,0) | S7: =IF($E7<S$4,($G7*1.3)/4,0)
H8: =IF($E8<I$4,($G8*1.3)/4,0) | I8: =IF($E8<J$4,($G8*1.3)/4,0) | J8: =IF($E8<K$4,($G8*1.3)/4,0) | K8: =IF($E8<L$4,($G8*1.3)/4,0) | L8: =IF($E8<M$4,($G8*1.3)/4,0) | M8: =IF($E8<N$4,($G8*1.3)/4,0) | N8: =IF($E8<O$4,($G8*1.3)/4,0) | O8: =IF($E8<P$4,($G8*1.3)/4,0) | ... R8: =IF($E8<S$4,($G8*1.3)/4,0) | S8: =IF($E8<S$4,($G8*1.3)/4,0)
H9: =IF($E9<I$4,($G9*1.3)/4,0) | I9: =IF($E9<J$4,($G9*1.3)/4,0) | J9: =IF($E9<K$4,($G9*1.3)/4,0) | K9: =IF($E9<L$4,($G9*1.3)/4,0) | L9: =IF($E9<M$4,($G9*1.3)/4,0) | M9: =IF($E9<N$4,($G9*1.3)/4,0) | N9: =IF($E9<O$4,($G9*1.3)/4,0) | O9: =IF($E9<P$4,($G9*1.3)/4,0) | ... R9: =IF($E9<S$4,($G9*1.3)/4,0) | S9: =IF($E9<S$4,($G9*1.3)/4,0)
H10: =IF($E10<I$4,($G10*1.3)/4,0) | I10: =IF($E10<J$4,($G10*1.3)/4,0) | J10: =IF($E10<K$4,($G10*1.3)/4,0) | K10: =IF($E10<L$4,($G10*1.3)/4,0) | L10: =IF($E10<M$4,($G10*1.3)/4,0) | M10: =IF($E10<N$4,($G10*1.3)/4,0) | N10: =IF($E10<O$4,($G10*1.3)/4,0) | O10: =IF($E10<P$4,($G10*1.3)/4,0) | ... R10: =IF($E10<S$4,($G10*1.3)/4,0) | S10: =IF($E10<S$4,($G10*1.3)/4,0)
H11: =IF($E11<I$4,($G11*1.3)/4,0) | I11: =IF($E11<J$4,($G11*1.3)/4,0) | J11: =IF($E11<K$4,($G11*1.3)/4,0) | K11: =IF($E11<L$4,($G11*1.3)/4,0) | L11: =IF($E11<M$4,($G11*1.3)/4,0) | M11: =IF($E11<N$4,($G11*1.3)/4,0) | N11: =IF($E11<O$4,($G11*1.3)/4,0) | O11: =IF($E11<P$4,($G11*1.3)/4,0) | ... R11: =IF($E11<S$4,($G11*1.3)/4,0) | S11: =IF($E11<S$4,($G11*1.3)/4,0)
H12: =IF($E12<I$4,($G12*1.3)/4,0) | I12: =IF($E12<J$4,($G12*1.3)/4,0) | J12: =IF($E12<K$4,($G12*1.3)/4,0) | K12: =IF($E12<L$4,($G12*1.3)/4,0) | L12: =IF($E12<M$4,($G12*1.3)/4,0) | M12: =IF($E12<N$4,($G12*1.3)/4,0) | N12: =IF($E12<O$4,($G12*1.3)/4,0) | O12: =IF($E12<P$4,($G12*1.3)/4,0) | ... R12: =IF($E12<S$4,($G12*1.3)/4,0) | S12: =IF($E12<S$4,($G12*1.3)/4,0)
H13: =IF($E13<I$4,($G13*1.3)/4,0) | I13: =IF($E13<J$4,($G13*1.3)/4,0) | J13: =IF($E13<K$4,($G13*1.3)/4,0) | K13: =IF($E13<L$4,($G13*1.3)/4,0) | L13: =IF($E13<M$4,($G13*1.3)/4,0) | M13: =IF($E13<N$4,($G13*1.3)/4,0) | N13: =IF($E13<O$4,($G13*1.3)/4,0) | O13: =IF($E13<P$4,($G13*1.3)/4,0) | ... R13: =IF($E13<S$4,($G13*1.3)/4,0) | S13: =IF($E13<S$4,($G13*1.3)/4,0)
H14: =IF($E14<I$4,($G14*1.3)/4,0) | I14: =IF($E14<J$4,($G14*1.3)/4,0) | J14: =IF($E14<K$4,($G14*1.3)/4,0) | K14: =IF($E14<L$4,($G14*1.3)/4,0) | L14: =IF($E14<M$4,($G14*1.3)/4,0) | M14: =IF($E14<N$4,($G14*1.3)/4,0) | N14: =IF($E14<O$4,($G14*1.3)/4,0) | O14: =IF($E14<P$4,($G14*1.3)/4,0) | ... R14: =IF($E14<S$4,($G14*1.3)/4,0) | S14: =IF($E14<S$4,($G14*1.3)/4,0)
H15: =IF($E15<I$4,($G15*1.3)/4,0) | I15: =IF($E15<J$4,($G15*1.3)/4,0) | J15: =IF($E15<K$4,($G15*1.3)/4,0) | K15: =IF($E15<L$4,($G15*1.3)/4,0) | L15: =IF($E15<M$4,($G15*1.3)/4,0) | M15: =IF($E15<N$4,($G15*1.3)/4,0) | N15: =IF($E15<O$4,($G15*1.3)/4,0) | O15: =IF($E15<P$4,($G15*1.3)/4,0) | ... R15: =IF($E15<S$4,($G15*1.3)/4,0) | S15: =IF($E15<S$4,($G15*1.3)/4,0)
H16: =IF($E16<I$4,($G16*1.3)/4,0) | I16: =IF($E16<J$4,($G16*1.3)/4,0) | J16: =IF($E16<K$4,($G16*1.3)/4,0) | K16: =IF($E16<L$4,($G16*1.3)/4,0) | L16: =IF($E16<M$4,($G16*1.3)/4,0) | M16: =IF($E16<N$4,($G16*1.3)/4,0) | N16: =IF($E16<O$4,($G16*1.3)/4,0) | O16: =IF($E16<P$4,($G16*1.3)/4,0) | ... R16: =IF($E16<S$4,($G16*1.3)/4,0) | S16: =IF($E16<S$4,($G16*1.3)/4,0)
H17: =IF($E17<I$4,($G17*1.3)/4,0) | I17: =IF($E17<J$4,($G17*1.3)/4,0) | J17: =IF($E17<K$4,($G17*1.3)/4,0) | K17: =IF($E17<L$4,($G17*1.3)/4,0) | L17: =IF($E17<M$4,($G17*1.3)/4,0) | M17: =IF($E17<N$4,($G17*1.3)/4,0) | N17: =IF($E17<O$4,($G17*1.3)/4,0) | O17: =IF($E17<P$4,($G17*1.3)/4,0) | ... R17: =IF($E17<S$4,($G17*1.3)/4,0) | S17: =IF($E17<S$4,($G17*1.3)/4,0)
... H24: =IF($E24<I$4,($G24*1.3)/4,0) | I24: =IF($E24<J$4,($G24*1.3)/4,0) | J24: =IF($E24<K$4,($G24*1.3)/4,0) | K24: =IF($E24<L$4,($G24*1.3)/4,0) | L24: =IF($E24<M$4,($G24*1.3)/4,0) | M24: =IF($E24<N$4,($G24*1.3)/4,0) | N24: =IF($E24<O$4,($G24*1.3)/4,0) | O24: =IF($E24<P$4,($G24*1.3)/4,0) | ... R24: =IF($E24<S$4,($G24*1.3)/4,0) | S24: =IF($E24<S$4,($G24*1.3)/4,0)
H25: =SUM(H6:H24) | I25: =SUM(I6:I24) | J25: =SUM(J6:J24) | K25: =SUM(K6:K24) | L25: =SUM(L6:L24) | M25: =SUM(M6:M24) | N25: =SUM(N6:N24) | O25: =SUM(O6:O24) | ... S25: =SUM(S6:S24)
A27: Non Headcount | H27: 2019 | J27: 2020 | N27: 2021 | R27: 2022
A28: Submitted by | B28: Department | C28: Description of Spend | D28: Justification | G28: Total Cost Estimate | H28: Q3 | I28: Q4 | J28: Q1 | K28: Q2 | L28: Q3 | M28: Q4 | N28: Q1 | O28: Q2 | P28: Q3 | Q28: Q4 | R28: Q1 | S28: Q2
A29: Heather | B29: Accounting | C29: Valuation PPA | D29: Valuation of Intangibles & Goodwill | G29: =I29 | I29: 15000
A30: Heather | B30: Accounting | C30: GT PPA Review | D30: External Audit Review of Valuation | G30: =I30 | I30: 30000
G41: =SUM(G29:G40) | H41: =SUM(H29:H34) | I41: =SUM(I29:I34) | J41: =SUM(J29:J34) | K41: =SUM(K29:K34) | L41: =SUM(L29:L34) | M41: =SUM(M29:M34) | N41: =SUM(N29:N34) | O41: =SUM(O29:O34) | ... S41: =SUM(S29:S34)

Sheet 8) Facilities
A1: Delta Incremental Costs
A3: Headcount | H3: 2019 | J3: 2020 | N3: 2021 | R3: 2022
H4: 43647 | I4: 43739 | J4: 43831 | K4: 43922 | L4: 44013 | M4: 44105 | N4: 44197 | O4: 44287 | P4: 44378 | Q4: 44470 | R4: 44562 | S4: 44652
A5: Submitted by | B5: Department | C5: TBH Title | D5: Description | E5: Hire Date | F5: Location | G5: Base Salary Estimate USD | H5: Q3 | I5: Q4 | J5: Q1 | K5: Q2 | L5: Q3 | M5: Q4 | N5: Q1 | O5: Q2 | P5: Q3 | Q5: Q4 | R5: Q1 | S5: Q2
H6: =IF($E6<I$4,($G6*1.3)/4,0) | I6: =IF($E6<J$4,($G6*1.3)/4,0) | J6: =IF($E6<K$4,($G6*1.3)/4,0) | K6: =IF($E6<L$4,($G6*1.3)/4,0) | L6: =IF($E6<M$4,($G6*1.3)/4,0) | M6: =IF($E6<N$4,($G6*1.3)/4,0) | N6: =IF($E6<O$4,($G6*1.3)/4,0) | O6: =IF($E6<P$4,($G6*1.3)/4,0) | ... R6: =IF($E6<S$4,($G6*1.3)/4,0) | S6: =IF($E6<S$4,($G6*1.3)/4,0)
H7: =IF($E7<I$4,($G7*1.3)/4,0) | I7: =IF($E7<J$4,($G7*1.3)/4,0) | J7: =IF($E7<K$4,($G7*1.3)/4,0) | K7: =IF($E7<L$4,($G7*1.3)/4,0) | L7: =IF($E7<M$4,($G7*1.3)/4,0) | M7: =IF($E7<N$4,($G7*1.3)/4,0) | N7: =IF($E7<O$4,($G7*1.3)/4,0) | O7: =IF($E7<P$4,($G7*1.3)/4,0) | ... R7: =IF($E7<S$4,($G7*1.3)/4,0) | S7: =IF($E7<S$4,($G7*1.3)/4,0)
H8: =IF($E8<I$4,($G8*1.3)/4,0) | I8: =IF($E8<J$4,($G8*1.3)/4,0) | J8: =IF($E8<K$4,($G8*1.3)/4,0) | K8: =IF($E8<L$4,($G8*1.3)/4,0) | L8: =IF($E8<M$4,($G8*1.3)/4,0) | M8: =IF($E8<N$4,($G8*1.3)/4,0) | N8: =IF($E8<O$4,($G8*1.3)/4,0) | O8: =IF($E8<P$4,($G8*1.3)/4,0) | ... R8: =IF($E8<S$4,($G8*1.3)/4,0) | S8: =IF($E8<S$4,($G8*1.3)/4,0)
H9: =IF($E9<I$4,($G9*1.3)/4,0) | I9: =IF($E9<J$4,($G9*1.3)/4,0) | J9: =IF($E9<K$4,($G9*1.3)/4,0) | K9: =IF($E9<L$4,($G9*1.3)/4,0) | L9: =IF($E9<M$4,($G9*1.3)/4,0) | M9: =IF($E9<N$4,($G9*1.3)/4,0) | N9: =IF($E9<O$4,($G9*1.3)/4,0) | O9: =IF($E9<P$4,($G9*1.3)/4,0) | ... R9: =IF($E9<S$4,($G9*1.3)/4,0) | S9: =IF($E9<S$4,($G9*1.3)/4,0)
H10: =IF($E10<I$4,($G10*1.3)/4,0) | I10: =IF($E10<J$4,($G10*1.3)/4,0) | J10: =IF($E10<K$4,($G10*1.3)/4,0) | K10: =IF($E10<L$4,($G10*1.3)/4,0) | L10: =IF($E10<M$4,($G10*1.3)/4,0) | M10: =IF($E10<N$4,($G10*1.3)/4,0) | N10: =IF($E10<O$4,($G10*1.3)/4,0) | O10: =IF($E10<P$4,($G10*1.3)/4,0) | ... R10: =IF($E10<S$4,($G10*1.3)/4,0) | S10: =IF($E10<S$4,($G10*1.3)/4,0)
H11: =IF($E11<I$4,($G11*1.3)/4,0) | I11: =IF($E11<J$4,($G11*1.3)/4,0) | J11: =IF($E11<K$4,($G11*1.3)/4,0) | K11: =IF($E11<L$4,($G11*1.3)/4,0) | L11: =IF($E11<M$4,($G11*1.3)/4,0) | M11: =IF($E11<N$4,($G11*1.3)/4,0) | N11: =IF($E11<O$4,($G11*1.3)/4,0) | O11: =IF($E11<P$4,($G11*1.3)/4,0) | ... R11: =IF($E11<S$4,($G11*1.3)/4,0) | S11: =IF($E11<S$4,($G11*1.3)/4,0)
H12: =IF($E12<I$4,($G12*1.3)/4,0) | I12: =IF($E12<J$4,($G12*1.3)/4,0) | J12: =IF($E12<K$4,($G12*1.3)/4,0) | K12: =IF($E12<L$4,($G12*1.3)/4,0) | L12: =IF($E12<M$4,($G12*1.3)/4,0) | M12: =IF($E12<N$4,($G12*1.3)/4,0) | N12: =IF($E12<O$4,($G12*1.3)/4,0) | O12: =IF($E12<P$4,($G12*1.3)/4,0) | ... R12: =IF($E12<S$4,($G12*1.3)/4,0) | S12: =IF($E12<S$4,($G12*1.3)/4,0)
H13: =IF($E13<I$4,($G13*1.3)/4,0) | I13: =IF($E13<J$4,($G13*1.3)/4,0) | J13: =IF($E13<K$4,($G13*1.3)/4,0) | K13: =IF($E13<L$4,($G13*1.3)/4,0) | L13: =IF($E13<M$4,($G13*1.3)/4,0) | M13: =IF($E13<N$4,($G13*1.3)/4,0) | N13: =IF($E13<O$4,($G13*1.3)/4,0) | O13: =IF($E13<P$4,($G13*1.3)/4,0) | ... R13: =IF($E13<S$4,($G13*1.3)/4,0) | S13: =IF($E13<S$4,($G13*1.3)/4,0)
H14: =IF($E14<I$4,($G14*1.3)/4,0) | I14: =IF($E14<J$4,($G14*1.3)/4,0) | J14: =IF($E14<K$4,($G14*1.3)/4,0) | K14: =IF($E14<L$4,($G14*1.3)/4,0) | L14: =IF($E14<M$4,($G14*1.3)/4,0) | M14: =IF($E14<N$4,($G14*1.3)/4,0) | N14: =IF($E14<O$4,($G14*1.3)/4,0) | O14: =IF($E14<P$4,($G14*1.3)/4,0) | ... R14: =IF($E14<S$4,($G14*1.3)/4,0) | S14: =IF($E14<S$4,($G14*1.3)/4,0)
H15: =IF($E15<I$4,($G15*1.3)/4,0) | I15: =IF($E15<J$4,($G15*1.3)/4,0) | J15: =IF($E15<K$4,($G15*1.3)/4,0) | K15: =IF($E15<L$4,($G15*1.3)/4,0) | L15: =IF($E15<M$4,($G15*1.3)/4,0) | M15: =IF($E15<N$4,($G15*1.3)/4,0) | N15: =IF($E15<O$4,($G15*1.3)/4,0) | O15: =IF($E15<P$4,($G15*1.3)/4,0) | ... R15: =IF($E15<S$4,($G15*1.3)/4,0) | S15: =IF($E15<S$4,($G15*1.3)/4,0)
H16: =IF($E16<I$4,($G16*1.3)/4,0) | I16: =IF($E16<J$4,($G16*1.3)/4,0) | J16: =IF($E16<K$4,($G16*1.3)/4,0) | K16: =IF($E16<L$4,($G16*1.3)/4,0) | L16: =IF($E16<M$4,($G16*1.3)/4,0) | M16: =IF($E16<N$4,($G16*1.3)/4,0) | N16: =IF($E16<O$4,($G16*1.3)/4,0) | O16: =IF($E16<P$4,($G16*1.3)/4,0) | ... R16: =IF($E16<S$4,($G16*1.3)/4,0) | S16: =IF($E16<S$4,($G16*1.3)/4,0)
H17: =IF($E17<I$4,($G17*1.3)/4,0) | I17: =IF($E17<J$4,($G17*1.3)/4,0) | J17: =IF($E17<K$4,($G17*1.3)/4,0) | K17: =IF($E17<L$4,($G17*1.3)/4,0) | L17: =IF($E17<M$4,($G17*1.3)/4,0) | M17: =IF($E17<N$4,($G17*1.3)/4,0) | N17: =IF($E17<O$4,($G17*1.3)/4,0) | O17: =IF($E17<P$4,($G17*1.3)/4,0) | ... R17: =IF($E17<S$4,($G17*1.3)/4,0) | S17: =IF($E17<S$4,($G17*1.3)/4,0)
... H24: =IF($E24<I$4,($G24*1.3)/4,0) | I24: =IF($E24<J$4,($G24*1.3)/4,0) | J24: =IF($E24<K$4,($G24*1.3)/4,0) | K24: =IF($E24<L$4,($G24*1.3)/4,0) | L24: =IF($E24<M$4,($G24*1.3)/4,0) | M24: =IF($E24<N$4,($G24*1.3)/4,0) | N24: =IF($E24<O$4,($G24*1.3)/4,0) | O24: =IF($E24<P$4,($G24*1.3)/4,0) | ... R24: =IF($E24<S$4,($G24*1.3)/4,0) | S24: =IF($E24<S$4,($G24*1.3)/4,0)
H25: =SUM(H6:H24) | I25: =SUM(I6:I24) | J25: =SUM(J6:J24) | K25: =SUM(K6:K24) | L25: =SUM(L6:L24) | M25: =SUM(M6:M24) | N25: =SUM(N6:N24) | O25: =SUM(O6:O24) | ... S25: =SUM(S6:S24)
A27: Non Headcount | H27: 2019 | J27: 2020 | N27: 2021 | R27: 2022
A28: Submitted by | B28: Department | C28: Description of Spend | D28: Justification | G28: Total Cost Estimate | H28: Q3 | I28: Q4 | J28: Q1 | K28: Q2 | L28: Q3 | M28: Q4 | N28: Q1 | O28: Q2 | P28: Q3 | Q28: Q4 | R28: Q1 | S28: Q2
A29: Peter Schaffer | B29: Delta | C29: Rent-Current premises | D29: Office Space -lease obligation through 6/31/2020 | G29: =SUM(I29:M29) | I29: 22963 | J29: 22963 | K29: 22963
A30: Nish,Peter&LB Email | B30: Workplace | C30: "Base" Rent for WeWork | D30: Assumes 26 heads Q1 - 28 heads Q3 - flat at 28 forward - numbers reflect cost to secure the space in Q1 | G30: =SUM(I30:O30) | J30: =(28*1839)*3 | K30: =(28*1839)*3 | L30: =(28*1839)*3 | M30: =(28*1839)*3
G41: =SUM(G29:G40) | H41: =SUM(H29:H34) | I41: =SUM(I29:I34) | J41: =SUM(J29:J34) | K41: =SUM(K29:K34) | L41: =SUM(L29:L34) | M41: =SUM(M29:M34) | N41: =SUM(N29:N34) | O41: =SUM(O29:O34) | ... S41: =SUM(S29:S34)

Sheet 11) IT-Infrastructure
A1: Delta Incremental Costs
A3: Headcount | H3: 2019 | J3: 2020 | N3: 2021 | R3: 2022
H4: 43647 | I4: 43739 | J4: 43831 | K4: 43922 | L4: 44013 | M4: 44105 | N4: 44197 | O4: 44287 | P4: 44378 | Q4: 44470 | R4: 44562 | S4: 44652
A5: Submitted by | B5: Department | C5: TBH Title | D5: Description | E5: Hire Date | F5: Location | G5: Base Salary Estimate USD | H5: Q3 | I5: Q4 | J5: Q1 | K5: Q2 | L5: Q3 | M5: Q4 | N5: Q1 | O5: Q2 | P5: Q3 | Q5: Q4 | R5: Q1 | S5: Q2
A6: n/a - utilize existing MSP/ HC IT support strategy for region | G6: 0 | H6: =IF($E6<I$4,($G6*1.3)/4,0) | I6: =IF($E6<J$4,($G6*1.3)/4,0) | J6: =IF($E6<K$4,($G6*1.3)/4,0) | K6: =IF($E6<L$4,($G6*1.3)/4,0) | L6: =IF($E6<M$4,($G6*1.3)/4,0) | M6: =IF($E6<N$4,($G6*1.3)/4,0) | N6: =IF($E6<O$4,($G6*1.3)/4,0) | O6: =IF($E6<P$4,($G6*1.3)/4,0) | ... R6: =IF($E6<S$4,($G6*1.3)/4,0) | S6: =IF($E6<S$4,($G6*1.3)/4,0)
H7: =IF($E7<I$4,($G7*1.3)/4,0) | I7: =IF($E7<J$4,($G7*1.3)/4,0) | J7: =IF($E7<K$4,($G7*1.3)/4,0) | K7: =IF($E7<L$4,($G7*1.3)/4,0) | L7: =IF($E7<M$4,($G7*1.3)/4,0) | M7: =IF($E7<N$4,($G7*1.3)/4,0) | N7: =IF($E7<O$4,($G7*1.3)/4,0) | O7: =IF($E7<P$4,($G7*1.3)/4,0) | ... R7: =IF($E7<S$4,($G7*1.3)/4,0) | S7: =IF($E7<S$4,($G7*1.3)/4,0)
H8: =IF($E8<I$4,($G8*1.3)/4,0) | I8: =IF($E8<J$4,($G8*1.3)/4,0) | J8: =IF($E8<K$4,($G8*1.3)/4,0) | K8: =IF($E8<L$4,($G8*1.3)/4,0) | L8: =IF($E8<M$4,($G8*1.3)/4,0) | M8: =IF($E8<N$4,($G8*1.3)/4,0) | N8: =IF($E8<O$4,($G8*1.3)/4,0) | O8: =IF($E8<P$4,($G8*1.3)/4,0) | ... R8: =IF($E8<S$4,($G8*1.3)/4,0) | S8: =IF($E8<S$4,($G8*1.3)/4,0)
H9: =IF($E9<I$4,($G9*1.3)/4,0) | I9: =IF($E9<J$4,($G9*1.3)/4,0) | J9: =IF($E9<K$4,($G9*1.3)/4,0) | K9: =IF($E9<L$4,($G9*1.3)/4,0) | L9: =IF($E9<M$4,($G9*1.3)/4,0) | M9: =IF($E9<N$4,($G9*1.3)/4,0) | N9: =IF($E9<O$4,($G9*1.3)/4,0) | O9: =IF($E9<P$4,($G9*1.3)/4,0) | ... R9: =IF($E9<S$4,($G9*1.3)/4,0) | S9: =IF($E9<S$4,($G9*1.3)/4,0)
H10: =IF($E10<I$4,($G10*1.3)/4,0) | I10: =IF($E10<J$4,($G10*1.3)/4,0) | J10: =IF($E10<K$4,($G10*1.3)/4,0) | K10: =IF($E10<L$4,($G10*1.3)/4,0) | L10: =IF($E10<M$4,($G10*1.3)/4,0) | M10: =IF($E10<N$4,($G10*1.3)/4,0) | N10: =IF($E10<O$4,($G10*1.3)/4,0) | O10: =IF($E10<P$4,($G10*1.3)/4,0) | ... R10: =IF($E10<S$4,($G10*1.3)/4,0) | S10: =IF($E10<S$4,($G10*1.3)/4,0)
H11: =IF($E11<I$4,($G11*1.3)/4,0) | I11: =IF($E11<J$4,($G11*1.3)/4,0) | J11: =IF($E11<K$4,($G11*1.3)/4,0) | K11: =IF($E11<L$4,($G11*1.3)/4,0) | L11: =IF($E11<M$4,($G11*1.3)/4,0) | M11: =IF($E11<N$4,($G11*1.3)/4,0) | N11: =IF($E11<O$4,($G11*1.3)/4,0) | O11: =IF($E11<P$4,($G11*1.3)/4,0) | ... R11: =IF($E11<S$4,($G11*1.3)/4,0) | S11: =IF($E11<S$4,($G11*1.3)/4,0)
H12: =IF($E12<I$4,($G12*1.3)/4,0) | I12: =IF($E12<J$4,($G12*1.3)/4,0) | J12: =IF($E12<K$4,($G12*1.3)/4,0) | K12: =IF($E12<L$4,($G12*1.3)/4,0) | L12: =IF($E12<M$4,($G12*1.3)/4,0) | M12: =IF($E12<N$4,($G12*1.3)/4,0) | N12: =IF($E12<O$4,($G12*1.3)/4,0) | O12: =IF($E12<P$4,($G12*1.3)/4,0) | ... R12: =IF($E12<S$4,($G12*1.3)/4,0) | S12: =IF($E12<S$4,($G12*1.3)/4,0)
H13: =IF($E13<I$4,($G13*1.3)/4,0) | I13: =IF($E13<J$4,($G13*1.3)/4,0) | J13: =IF($E13<K$4,($G13*1.3)/4,0) | K13: =IF($E13<L$4,($G13*1.3)/4,0) | L13: =IF($E13<M$4,($G13*1.3)/4,0) | M13: =IF($E13<N$4,($G13*1.3)/4,0) | N13: =IF($E13<O$4,($G13*1.3)/4,0) | O13: =IF($E13<P$4,($G13*1.3)/4,0) | ... R13: =IF($E13<S$4,($G13*1.3)/4,0) | S13: =IF($E13<S$4,($G13*1.3)/4,0)
H14: =IF($E14<I$4,($G14*1.3)/4,0) | I14: =IF($E14<J$4,($G14*1.3)/4,0) | J14: =IF($E14<K$4,($G14*1.3)/4,0) | K14: =IF($E14<L$4,($G14*1.3)/4,0) | L14: =IF($E14<M$4,($G14*1.3)/4,0) | M14: =IF($E14<N$4,($G14*1.3)/4,0) | N14: =IF($E14<O$4,($G14*1.3)/4,0) | O14: =IF($E14<P$4,($G14*1.3)/4,0) | ... R14: =IF($E14<S$4,($G14*1.3)/4,0) | S14: =IF($E14<S$4,($G14*1.3)/4,0)
H15: =IF($E15<I$4,($G15*1.3)/4,0) | I15: =IF($E15<J$4,($G15*1.3)/4,0) | J15: =IF($E15<K$4,($G15*1.3)/4,0) | K15: =IF($E15<L$4,($G15*1.3)/4,0) | L15: =IF($E15<M$4,($G15*1.3)/4,0) | M15: =IF($E15<N$4,($G15*1.3)/4,0) | N15: =IF($E15<O$4,($G15*1.3)/4,0) | O15: =IF($E15<P$4,($G15*1.3)/4,0) | ... R15: =IF($E15<S$4,($G15*1.3)/4,0) | S15: =IF($E15<S$4,($G15*1.3)/4,0)
H16: =IF($E16<I$4,($G16*1.3)/4,0) | I16: =IF($E16<J$4,($G16*1.3)/4,0) | J16: =IF($E16<K$4,($G16*1.3)/4,0) | K16: =IF($E16<L$4,($G16*1.3)/4,0) | L16: =IF($E16<M$4,($G16*1.3)/4,0) | M16: =IF($E16<N$4,($G16*1.3)/4,0) | N16: =IF($E16<O$4,($G16*1.3)/4,0) | O16: =IF($E16<P$4,($G16*1.3)/4,0) | ... R16: =IF($E16<S$4,($G16*1.3)/4,0) | S16: =IF($E16<S$4,($G16*1.3)/4,0)
H17: =IF($E17<I$4,($G17*1.3)/4,0) | I17: =IF($E17<J$4,($G17*1.3)/4,0) | J17: =IF($E17<K$4,($G17*1.3)/4,0) | K17: =IF($E17<L$4,($G17*1.3)/4,0) | L17: =IF($E17<M$4,($G17*1.3)/4,0) | M17: =IF($E17<N$4,($G17*1.3)/4,0) | N17: =IF($E17<O$4,($G17*1.3)/4,0) | O17: =IF($E17<P$4,($G17*1.3)/4,0) | ... R17: =IF($E17<S$4,($G17*1.3)/4,0) | S17: =IF($E17<S$4,($G17*1.3)/4,0)
H18: =IF($E18<I$4,($G18*1.3)/4,0) | I18: =IF($E18<J$4,($G18*1.3)/4,0) | J18: =IF($E18<K$4,($G18*1.3)/4,0) | K18: =IF($E18<L$4,($G18*1.3)/4,0) | L18: =IF($E18<M$4,($G18*1.3)/4,0) | M18: =IF($E18<N$4,($G18*1.3)/4,0) | N18: =IF($E18<O$4,($G18*1.3)/4,0) | O18: =IF($E18<P$4,($G18*1.3)/4,0) | ... R18: =IF($E18<S$4,($G18*1.3)/4,0) | S18: =IF($E18<S$4,($G18*1.3)/4,0)
... H24: =IF($E24<I$4,($G24*1.3)/4,0) | I24: =IF($E24<J$4,($G24*1.3)/4,0) | J24: =IF($E24<K$4,($G24*1.3)/4,0) | K24: =IF($E24<L$4,($G24*1.3)/4,0) | L24: =IF($E24<M$4,($G24*1.3)/4,0) | M24: =IF($E24<N$4,($G24*1.3)/4,0) | N24: =IF($E24<O$4,($G24*1.3)/4,0) | O24: =IF($E24<P$4,($G24*1.3)/4,0) | ... R24: =IF($E24<S$4,($G24*1.3)/4,0) | S24: =IF($E24<S$4,($G24*1.3)/4,0)
H25: =SUM(H6:H24) | I25: =SUM(I6:I24) | J25: =SUM(J6:J24) | K25: =SUM(K6:K24) | L25: =SUM(L6:L24) | M25: =SUM(M6:M24) | N25: =SUM(N6:N24) | O25: =SUM(O6:O24) | ... S25: =SUM(S6:S24)
A27: Non Headcount | H27: 2019 | J27: 2020 | N27: 2021 | R27: 2022
A28: Submitted by | B28: Department | C28: Description of Spend | D28: Justification | G28: Total Cost Estimate | H28: Q3 | I28: Q4 | J28: Q1 | K28: Q2 | L28: Q3 | M28: Q4 | N28: Q1 | O28: Q2 | P28: Q3 | Q28: Q4 | R28: Q1 | S28: Q2
A29: BBragg | B29: 8010 | C29: Laptops/ Monitors / Docs | D29: Hitrust compliance and employee productivity standard, Apac expensed in Qtr | G29: =SUM(H29:M29) | I29: =18*5000
A30: BBragg | B30: 8010 | C30: Zoom Equipment | D30: Presumes conference needs at location met by facility and laptops | G30: n/a
A31: BBragg | B31: 8010 | C31: Fitbit-Corp Wifi | D31: Presumes co-working location (e.g. WeWork?) and procuring as a service from the facility. | G31: =SUM(H31:M31) | I31: 10000 | J31: 10000 | K31: 10000 | L31: 10000 | M31: 10000
A32: BBragg | B32: 8010 | C32: Printers | D32: Presume co-working location provided and usage billed to local CC | G32: n/a
A33: BBragg | B33: 8010 | C33: Google/ Slack /Zoom /O365 | D33: Sufficient existing terms | G33: n/a
A34: BBragg | B34: Likely Jonah Org as current model | C34: Special software : Adobe, Zepplin, Sketch | D34: Existing design tools and similar to FB standards used by ID | G34: =SUM(H34:M34) | I34: 10000 | M34: 10000
A35: BBragg | B35: 8010 | C35: Outside Services | D35: Temp IT Systems Engineer in APAC to support, transition and decom existing internal systems | G35: =SUM(H35:M35) | I35: 30000
G41: =SUM(G29:G40) | H41: =SUM(H29:H34) | I41: =SUM(I29:I34) | J41: =SUM(J29:J34) | K41: =SUM(K29:K34) | L41: =SUM(L29:L34) | M41: =SUM(M29:M34) | N41: =SUM(N29:N34) | O41: =SUM(O29:O34) | ... S41: =SUM(S29:S34)

Sheet 13) IT- Security
A1: Delta Incremental Costs
A3: Headcount | H3: 2019 | J3: 2020 | N3: 2021 | R3: 2022
H4: 43647 | I4: 43739 | J4: 43831 | K4: 43922 | L4: 44013 | M4: 44105 | N4: 44197 | O4: 44287 | P4: 44378 | Q4: 44470 | R4: 44562 | S4: 44652
A5: Submitted by | B5: Department | C5: TBH Title | D5: Description | E5: Hire Date | F5: Location | G5: Base Salary Estimate USD | H5: Q3 | I5: Q4 | J5: Q1 | K5: Q2 | L5: Q3 | M5: Q4 | N5: Q1 | O5: Q2 | P5: Q3 | Q5: Q4 | R5: Q1 | S5: Q2
H6: =IF($E6<I$4,($G6*1.3)/4,0) | I6: =IF($E6<J$4,($G6*1.3)/4,0) | J6: =IF($E6<K$4,($G6*1.3)/4,0) | K6: =IF($E6<L$4,($G6*1.3)/4,0) | L6: =IF($E6<M$4,($G6*1.3)/4,0) | M6: =IF($E6<N$4,($G6*1.3)/4,0) | N6: =IF($E6<O$4,($G6*1.3)/4,0) | O6: =IF($E6<P$4,($G6*1.3)/4,0) | ... R6: =IF($E6<S$4,($G6*1.3)/4,0) | S6: =IF($E6<S$4,($G6*1.3)/4,0)
H7: =IF($E7<I$4,($G7*1.3)/4,0) | I7: =IF($E7<J$4,($G7*1.3)/4,0) | J7: =IF($E7<K$4,($G7*1.3)/4,0) | K7: =IF($E7<L$4,($G7*1.3)/4,0) | L7: =IF($E7<M$4,($G7*1.3)/4,0) | M7: =IF($E7<N$4,($G7*1.3)/4,0) | N7: =IF($E7<O$4,($G7*1.3)/4,0) | O7: =IF($E7<P$4,($G7*1.3)/4,0) | ... R7: =IF($E7<S$4,($G7*1.3)/4,0) | S7: =IF($E7<S$4,($G7*1.3)/4,0)
H8: =IF($E8<I$4,($G8*1.3)/4,0) | I8: =IF($E8<J$4,($G8*1.3)/4,0) | J8: =IF($E8<K$4,($G8*1.3)/4,0) | K8: =IF($E8<L$4,($G8*1.3)/4,0) | L8: =IF($E8<M$4,($G8*1.3)/4,0) | M8: =IF($E8<N$4,($G8*1.3)/4,0) | N8: =IF($E8<O$4,($G8*1.3)/4,0) | O8: =IF($E8<P$4,($G8*1.3)/4,0) | ... R8: =IF($E8<S$4,($G8*1.3)/4,0) | S8: =IF($E8<S$4,($G8*1.3)/4,0)
H9: =IF($E9<I$4,($G9*1.3)/4,0) | I9: =IF($E9<J$4,($G9*1.3)/4,0) | J9: =IF($E9<K$4,($G9*1.3)/4,0) | K9: =IF($E9<L$4,($G9*1.3)/4,0) | L9: =IF($E9<M$4,($G9*1.3)/4,0) | M9: =IF($E9<N$4,($G9*1.3)/4,0) | N9: =IF($E9<O$4,($G9*1.3)/4,0) | O9: =IF($E9<P$4,($G9*1.3)/4,0) | ... R9: =IF($E9<S$4,($G9*1.3)/4,0) | S9: =IF($E9<S$4,($G9*1.3)/4,0)
H10: =IF($E10<I$4,($G10*1.3)/4,0) | I10: =IF($E10<J$4,($G10*1.3)/4,0) | J10: =IF($E10<K$4,($G10*1.3)/4,0) | K10: =IF($E10<L$4,($G10*1.3)/4,0) | L10: =IF($E10<M$4,($G10*1.3)/4,0) | M10: =IF($E10<N$4,($G10*1.3)/4,0) | N10: =IF($E10<O$4,($G10*1.3)/4,0) | O10: =IF($E10<P$4,($G10*1.3)/4,0) | ... R10: =IF($E10<S$4,($G10*1.3)/4,0) | S10: =IF($E10<S$4,($G10*1.3)/4,0)
H11: =IF($E11<I$4,($G11*1.3)/4,0) | I11: =IF($E11<J$4,($G11*1.3)/4,0) | J11: =IF($E11<K$4,($G11*1.3)/4,0) | K11: =IF($E11<L$4,($G11*1.3)/4,0) | L11: =IF($E11<M$4,($G11*1.3)/4,0) | M11: =IF($E11<N$4,($G11*1.3)/4,0) | N11: =IF($E11<O$4,($G11*1.3)/4,0) | O11: =IF($E11<P$4,($G11*1.3)/4,0) | ... R11: =IF($E11<S$4,($G11*1.3)/4,0) | S11: =IF($E11<S$4,($G11*1.3)/4,0)
H12: =IF($E12<I$4,($G12*1.3)/4,0) | I12: =IF($E12<J$4,($G12*1.3)/4,0) | J12: =IF($E12<K$4,($G12*1.3)/4,0) | K12: =IF($E12<L$4,($G12*1.3)/4,0) | L12: =IF($E12<M$4,($G12*1.3)/4,0) | M12: =IF($E12<N$4,($G12*1.3)/4,0) | N12: =IF($E12<O$4,($G12*1.3)/4,0) | O12: =IF($E12<P$4,($G12*1.3)/4,0) | ... R12: =IF($E12<S$4,($G12*1.3)/4,0) | S12: =IF($E12<S$4,($G12*1.3)/4,0)
H13: =IF($E13<I$4,($G13*1.3)/4,0) | I13: =IF($E13<J$4,($G13*1.3)/4,0) | J13: =IF($E13<K$4,($G13*1.3)/4,0) | K13: =IF($E13<L$4,($G13*1.3)/4,0) | L13: =IF($E13<M$4,($G13*1.3)/4,0) | M13: =IF($E13<N$4,($G13*1.3)/4,0) | N13: =IF($E13<O$4,($G13*1.3)/4,0) | O13: =IF($E13<P$4,($G13*1.3)/4,0) | ... R13: =IF($E13<S$4,($G13*1.3)/4,0) | S13: =IF($E13<S$4,($G13*1.3)/4,0)
H14: =IF($E14<I$4,($G14*1.3)/4,0) | I14: =IF($E14<J$4,($G14*1.3)/4,0) | J14: =IF($E14<K$4,($G14*1.3)/4,0) | K14: =IF($E14<L$4,($G14*1.3)/4,0) | L14: =IF($E14<M$4,($G14*1.3)/4,0) | M14: =IF($E14<N$4,($G14*1.3)/4,0) | N14: =IF($E14<O$4,($G14*1.3)/4,0) | O14: =IF($E14<P$4,($G14*1.3)/4,0) | ... R14: =IF($E14<S$4,($G14*1.3)/4,0) | S14: =IF($E14<S$4,($G14*1.3)/4,0)
H15: =IF($E15<I$4,($G15*1.3)/4,0) | I15: =IF($E15<J$4,($G15*1.3)/4,0) | J15: =IF($E15<K$4,($G15*1.3)/4,0) | K15: =IF($E15<L$4,($G15*1.3)/4,0) | L15: =IF($E15<M$4,($G15*1.3)/4,0) | M15: =IF($E15<N$4,($G15*1.3)/4,0) | N15: =IF($E15<O$4,($G15*1.3)/4,0) | O15: =IF($E15<P$4,($G15*1.3)/4,0) | ... R15: =IF($E15<S$4,($G15*1.3)/4,0) | S15: =IF($E15<S$4,($G15*1.3)/4,0)
H16: =IF($E16<I$4,($G16*1.3)/4,0) | I16: =IF($E16<J$4,($G16*1.3)/4,0) | J16: =IF($E16<K$4,($G16*1.3)/4,0) | K16: =IF($E16<L$4,($G16*1.3)/4,0) | L16: =IF($E16<M$4,($G16*1.3)/4,0) | M16: =IF($E16<N$4,($G16*1.3)/4,0) | N16: =IF($E16<O$4,($G16*1.3)/4,0) | O16: =IF($E16<P$4,($G16*1.3)/4,0) | ... R16: =IF($E16<S$4,($G16*1.3)/4,0) | S16: =IF($E16<S$4,($G16*1.3)/4,0)
H17: =IF($E17<I$4,($G17*1.3)/4,0) | I17: =IF($E17<J$4,($G17*1.3)/4,0) | J17: =IF($E17<K$4,($G17*1.3)/4,0) | K17: =IF($E17<L$4,($G17*1.3)/4,0) | L17: =IF($E17<M$4,($G17*1.3)/4,0) | M17: =IF($E17<N$4,($G17*1.3)/4,0) | N17: =IF($E17<O$4,($G17*1.3)/4,0) | O17: =IF($E17<P$4,($G17*1.3)/4,0) | ... R17: =IF($E17<S$4,($G17*1.3)/4,0) | S17: =IF($E17<S$4,($G17*1.3)/4,0)
